Workbook

Sheet Menu
D2: SINAPI
D3: Sistema Nacional de Pesquisa de Custos e Índices da Construção Civil
B5: =HYPERLINK("#Busca!$B$8","Pesquisa") | D5: Permite a pesquisa de insumos ou composições, por termos não consecutivos, com filtro "contém" e "não contém"
B7: =HYPERLINK("#'ISD'!$F$11","Insumos Não Desonerado") | D7: Relatório de preços de insumos sem desoneração para as 27 UF. Inclui link para as fichas de especificação técnica dos insumos.
B9: =HYPERLINK("#'ICD'!$F$11","Insumos Desonerado") | D9: Relatório de preços de insumos com desoneração para as 27 UF. Inclui link para as fichas de especificação técnica dos insumos.

Sheet ISD
A1: SINAPI - Sistema Nacional de Pesquisa de Custos e Índices da Construção Civil
A2: RELATÓRIO DE PREÇOS DE INSUMOS - ENCARGOS SOCIAIS SEM DESONERAÇÃO
A3: Mês de Referência: | B3: 08/2026 | E3: Encargos sociais sobre a mão de obra:
A4: Data de emissão: | B4: 11/09/2026 | E4: (SEM DESONERAÇÃO) | F4: AC | G4: AL | H4: AM | I4: AP | J4: BA | K4: CE | L4: DF | M4: ES | N4: GO | O4: MA | P4: MG | Q4: MS | R4: MT | S4: PA | T4: PB | U4: PE | V4: PI | W4: PR | X4: RJ | Y4: RN | Z4: RO | AA4: RR | AB4: RS | AC4: SC | AD4: SE | AE4: SP | AF4: TO
E5: Localidade | F5: RIO BRANCO | G5: MACEIO | H5: MANAUS | I5: MACAPA | J5: SALVADOR | K5: FORTALEZA | L5: BRASILIA | M5: VITORIA | N5: GOIANIA | O5: SAO LUIS | P5: BELO HORIZONTE | Q5: CAMPO GRANDE | R5: CUIABA | S5: BELEM | T5: JOAO PESSOA | U5: RECIFE | V5: TERESINA | W5: CURITIBA | X5: RIO DE JANEIRO | Y5: NATAL | Z5: PORTO VELHO | AA5: BOA VISTA | AB5: PORTO ALEGRE | AC5: FLORIANOPOLIS | AD5: ARACAJU | AE5: SAO PAULO | AF5: PALMAS
A6: Origem de preço: | B6: C = COLETADO | C6: CR = COEFICIENTE DE REPRESENTATIVIDADE | E6: Horista | F6: 1.1261 | G6: 1.1612 | H6: 1.1416 | I6: 1.1518 | J6: 1.1773 | K6: 1.1561 | L6: 1.1008 | M6: 1.183 | N6: 1.0772 | O6: 1.1411 | P6: 1.1623 | Q6: 1.1571 | R6: 1.0533 | S6: 1.1942 | T6: 1.1819 | U6: 1.1463 | V6: 1.1378 | W6: 1.1628 | X6: 1.1249 | Y6: 1.1683 | Z6: 1.1571 | AA6: 1.1479 | AB6: 1.1195 | AC6: 1.1447 | AD6: 1.1151 | AE6: 1.1501 | AF6: 1.1523
A7: Preço em branco para determinado estado significa que não houve coleta mínima de preços no mês de referência | E7: Mensalista | F7: 0.6903 | G7: 0.7125 | H7: 0.708 | I7: 0.7006 | J7: 0.7285 | K7: 0.7246 | L7: 0.6994 | M7: 0.7385 | N7: 0.6928 | O7: 0.713 | P7: 0.7383 | Q7: 0.7157 | R7: 0.6783 | S7: 0.727 | T7: 0.7266 | U7: 0.7067 | V7: 0.7159 | W7: 0.7242 | X7: 0.6966 | Y7: 0.7229 | Z7: 0.7065 | AA7: 0.7035 | AB7: 0.6929 | AC7: 0.7103 | AD7: 0.6972 | AE7: 0.7118 | AF7: 0.7198
A9: Acessar Fichas de Especificação Técnico dos Insumos | E9: Preços Medianos (R$):
A10: Classificação | B10: Código do Insumo | C10: Descrição do Insumo | D10: Unidade | E10: Origem de Preço | F10: AC | G10: AL | H10: AM | I10: AP | J10: BA | K10: CE | L10: DF | M10: ES | N10: GO | O10: MA | P10: MG | Q10: MS | R10: MT | S10: PA | T10: PB | U10: PE | V10: PI | W10: PR | X10: RJ | Y10: RN | Z10: RO | AA10: RR | AB10: RS | AC10: SC | AD10: SE | AE10: SP | AF10: TO
A11: ENCARGOS COMPLEMENTARES | B11: 37370 | C11: ALIMENTACAO - HORISTA (COLETADO CAIXA - ENCARGOS COMPLEMENTARES) | D11: H | E11: C | F11: 3.4 | G11: 2.68 | H11: 5.58 | I11: 0.66 | J11: 5 | K11: 4.15 | L11: 4.29 | M11: 7.63 | N11: 3.61 | O11: 2.2 | P11: 2.41 | Q11: 1.73 | R11: 2.9 | S11: 5.15 | T11: 1.82 | U11: 3.06 | V11: 2.49 | W11: 5.96 | X11: 4.78 | Y11: 4.93 | Z11: 3.76 | AA11: 3.52 | AB11: 1.82 | AC11: 0.01 | AD11: 2.96 | AE11: 4.48 | AF11: 2.39
A12: MATERIAL | B12: 370 | C12: AREIA MEDIA - POSTO JAZIDA/FORNECEDOR (RETIRADO NA JAZIDA, SEM TRANSPORTE) | D12: M3 | E12: CR | F12: 144.38 | G12: 120 | H12: 105 | I12: 150 | J12: 139 | K12: 140 | L12: 245.64 | M12: 95 | N12: 222.45 | O12: 150 | P12: 165 | Q12: 82 | R12: 130 | S12: 120 | T12: 140 | U12: 140 | V12: 96.25 | W12: 119.76 | X12: 105 | Y12: 130 | Z12: 180 | AA12: 70 | AB12: 102 | AC12: 148 | AD12: 115 | AE12: 92 | AF12: 157.85
A13: MATERIAL | B13: 34353 | C13: ARGAMASSA COLANTE AC II | D13: KG | E13: CR | F13: 2.66 | G13: 1.86 | H13: 2.36 | I13: 2.1 | J13: 1.69 | K13: 2.21 | L13: 1.24 | M13: 1.39 | N13: 1.58 | O13: 1.63 | P13: 1.3 | Q13: 1.76 | R13: 2.29 | S13: 1.67 | T13: 1.56 | U13: 2.04 | V13: 1.45 | W13: 1.52 | X13: 1.47 | Y13: 1.76 | Z13: 2.04 | AA13: 3.25 | AB13: 1.45 | AC13: 1.39 | AD13: 1.86 | AE13: 1.3 | AF13: 1.58
A14: EQUIPAMENTO (AQUISIÇÃO) | B14: 10535 | C14: BETONEIRA, CAPACIDADE NOMINAL 400 L, CAPACIDADE DE MISTURA 280 L, MOTOR ELETRICO TRIFASICO 220/380 V, POTENCIA 2 CV, SEM CARREGADOR | D14: UN | E14: C | F14: 5749 | G14: 4800 | H14: 5214.65 | I14: 5950 | J14: 5615 | K14: 5809 | L14: 5200 | M14: 5265 | N14: 5800 | O14: 6043.35 | P14: 6447.5 | Q14: 4990 | R14: 5798.6 | S14: 5999.95 | U14: 5439 | V14: 6880.24 | W14: 5518.25 | X14: 5380 | Y14: 5200 | Z14: 6214 | AA14: 5445 | AB14: 4799.9 | AC14: 5290.68 | AE14: 5590 | AF14: 5685.01
A15: MATERIAL | B15: 1106 | C15: CAL HIDRATADA CH-I PARA ARGAMASSAS | D15: KG | E15: C | F15: 2.64 | G15: 1.25 | H15: 1.19 | I15: 1.34 | J15: 1.72 | K15: 1.34 | L15: 1.58 | M15: 1.56 | N15: 1.35 | O15: 1.34 | P15: 1.33 | Q15: 1.3 | R15: 1.25 | S15: 1.34 | T15: 1.25 | U15: 1.8 | V15: 1.34 | W15: 0.83 | X15: 1.36 | Y15: 0.69 | Z15: 1.61 | AA15: 1.34 | AB15: 1.06 | AC15: 0.99 | AD15: 1.4 | AE15: 1.1 | AF15: 1.6
A16: MATERIAL | B16: 1379 | C16: CIMENTO PORTLAND COMPOSTO CP II-32 | D16: KG | E16: C | F16: 1.38 | G16: 0.96 | H16: 1.03 | I16: 1.14 | J16: 1.06 | K16: 0.84 | L16: 0.78 | M16: 0.74 | N16: 0.84 | O16: 1.11 | P16: 0.78 | Q16: 0.9 | R16: 1.05 | S16: 1.08 | T16: 0.88 | U16: 0.91 | V16: 1.14 | W16: 0.79 | X16: 0.68 | Y16: 0.88 | Z16: 1.3 | AA16: 1.67 | AB16: 0.91 | AC16: 0.9 | AD16: 0.94 | AE16: 0.7 | AF16: 1
A17: ESPECIAIS | B17: 2705 | C17: ENERGIA ELETRICA ATE 2000 KWH INDUSTRIAL, SEM DEMANDA | D17: KWH | E17: CR | F17: 1.3 | G17: 1.11 | H17: 0.98 | I17: 1.07 | J17: 1.14 | K17: 0.99 | L17: 0.8 | M17: 1.01 | N17: 1.18 | O17: 1.09 | P17: 1.16 | Q17: 1.28 | R17: 1.17 | S17: 1.22 | T17: 0.86 | U17: 1.03 | V17: 1.1 | W17: 0.85 | X17: 1.29 | Y17: 1.01 | Z17: 1.6 | AA17: 0.99 | AB17: 1.12 | AC17: 0.89 | AD17: 1 | AE17: 0.87 | AF17: 1.35
A18: ENCARGOS COMPLEMENTARES | B18: 43488 | C18: EPI - FAMILIA OPERADOR ESCAVADEIRA - HORISTA (ENCARGOS COMPLEMENTARES - COLETADO CAIXA) | D18: H | E18: C | F18: 0.91 | G18: 0.91 | H18: 0.92 | I18: 1.09 | J18: 0.89 | K18: 0.94 | L18: 0.79 | M18: 0.8 | N18: 0.71 | O18: 0.83 | P18: 0.9 | Q18: 0.9 | R18: 1.08 | S18: 1.11 | T18: 1.05 | U18: 0.92 | V18: 1.13 | W18: 1.03 | X18: 1.07 | Y18: 0.78 | Z18: 0.98 | AA18: 1.16 | AB18: 1.02 | AC18: 0.97 | AD18: 0.8 | AE18: 0.92 | AF18: 1
A19: ENCARGOS COMPLEMENTARES | B19: 43489 | C19: EPI - FAMILIA PEDREIRO - HORISTA (ENCARGOS COMPLEMENTARES - COLETADO CAIXA) | D19: H | E19: C | F19: 1.46 | G19: 1.45 | H19: 1.46 | I19: 1.74 | J19: 1.41 | K19: 1.5 | L19: 1.26 | M19: 1.28 | N19: 1.13 | O19: 1.32 | P19: 1.43 | Q19: 1.43 | R19: 1.72 | S19: 1.76 | T19: 1.68 | U19: 1.47 | V19: 1.81 | W19: 1.64 | X19: 1.71 | Y19: 1.25 | Z19: 1.56 | AA19: 1.85 | AB19: 1.62 | AC19: 1.55 | AD19: 1.28 | AE19: 1.47 | AF19: 1.6
A20: ENCARGOS COMPLEMENTARES | B20: 43491 | C20: EPI - FAMILIA SERVENTE - HORISTA (ENCARGOS COMPLEMENTARES - COLETADO CAIXA) | D20: H | E20: C | F20: 1.53 | G20: 1.52 | H20: 1.53 | I20: 1.82 | J20: 1.48 | K20: 1.57 | L20: 1.32 | M20: 1.34 | N20: 1.18 | O20: 1.38 | P20: 1.5 | Q20: 1.5 | R20: 1.8 | S20: 1.85 | T20: 1.75 | U20: 1.54 | V20: 1.89 | W20: 1.71 | X20: 1.79 | Y20: 1.31 | Z20: 1.63 | AA20: 1.94 | AB20: 1.7 | AC20: 1.62 | AD20: 1.34 | AE20: 1.54 | AF20: 1.67
A21: ENCARGOS COMPLEMENTARES | B21: 37372 | C21: EXAMES - HORISTA (COLETADO CAIXA - ENCARGOS COMPLEMENTARES) | D21: H | E21: C | F21: 1.32 | G21: 1.4 | H21: 1.29 | I21: 1.3 | J21: 1.49 | K21: 1.48 | L21: 1.31 | M21: 1.62 | N21: 1.58 | O21: 1.36 | P21: 1.57 | Q21: 1.67 | R21: 1.62 | S21: 1.51 | T21: 1.56 | U21: 1.24 | V21: 1.42 | W21: 1.58 | X21: 1.25 | Y21: 1.55 | Z21: 1.52 | AA21: 1.36 | AB21: 1.36 | AC21: 1.65 | AD21: 1.39 | AE21: 1.43 | AF21: 1.59
A22: ENCARGOS COMPLEMENTARES | B22: 43464 | C22: FERRAMENTAS - FAMILIA OPERADOR ESCAVADEIRA - HORISTA (ENCARGOS COMPLEMENTARES - COLETADO CAIXA) | D22: H | E22: C | F22: 0.03 | G22: 0.02 | H22: 0.02 | I22: 0.03 | J22: 0.02 | K22: 0.02 | L22: 0.03 | M22: 0.02 | N22: 0.02 | O22: 0.03 | P22: 0.03 | Q22: 0.02 | R22: 0.03 | S22: 0.03 | T22: 0.03 | U22: 0.02 | V22: 0.05 | W22: 0.02 | X22: 0.02 | Y22: 0.03 | Z22: 0.03 | AA22: 0.03 | AB22: 0.03 | AC22: 0.03 | AD22: 0.02 | AE22: 0.02 | AF22: 0.03
A23: ENCARGOS COMPLEMENTARES | B23: 43465 | C23: FERRAMENTAS - FAMILIA PEDREIRO - HORISTA (ENCARGOS COMPLEMENTARES - COLETADO CAIXA) | D23: H | E23: C | F23: 0.7 | G23: 0.6 | H23: 0.57 | I23: 0.65 | J23: 0.59 | K23: 0.6 | L23: 0.71 | M23: 0.68 | N23: 0.62 | O23: 0.73 | P23: 0.8 | Q23: 0.81 | R23: 0.74 | S23: 0.65 | T23: 0.63 | U23: 0.6 | V23: 0.9 | W23: 0.6 | X23: 0.64 | Y23: 0.66 | Z23: 0.74 | AA23: 0.63 | AB23: 0.71 | AC23: 0.72 | AD23: 0.61 | AE23: 0.73 | AF23: 0.83
A24: ENCARGOS COMPLEMENTARES | B24: 43467 | C24: FERRAMENTAS - FAMILIA SERVENTE - HORISTA (ENCARGOS COMPLEMENTARES - COLETADO CAIXA) | D24: H | E24: C | F24: 0.6 | G24: 0.48 | H24: 0.57 | I24: 0.61 | J24: 0.47 | K24: 0.57 | L24: 0.58 | M24: 0.57 | N24: 0.56 | O24: 0.58 | P24: 0.67 | Q24: 0.49 | R24: 0.6 | S24: 0.56 | T24: 0.58 | U24: 0.5 | V24: 1 | W24: 0.42 | X24: 0.56 | Y24: 0.62 | Z24: 0.63 | AA24: 0.64 | AB24: 0.57 | AC24: 0.6 | AD24: 0.49 | AE24: 0.57 | AF24: 0.69
A25: MAO DE OBRA | B25: 37666 | C25: OPERADOR DE BETONEIRA ESTACIONARIA / MISTURADOR (HORISTA) | D25: H | E25: CR | F25: 17.73 | G25: 15.56 | H25: 25.65 | I25: 15.29 | J25: 36.55 | K25: 22.76 | L25: 19.95 | M25: 24.42 | N25: 14.95 | O25: 27.04 | P25: 23.95 | Q25: 22.88 | R25: 17.24 | S25: 20.62 | T25: 16.62 | U25: 17.49 | V25: 23.02 | W25: 28.22 | X25: 24.96 | Y25: 20.9 | Z25: 20.57 | AA25: 16.64 | AB25: 26.28 | AC25: 33.47 | AD25: 20.74 | AE25: 26.7 | AF25: 16.2
A26: MAO DE OBRA | B26: 4750 | C26: PEDREIRO (HORISTA) | D26: H | E26: C | F26: 25.32 | G26: 20.27 | H26: 23.08 | I26: 22.37 | J26: 25.75 | K26: 23.35 | L26: 24.2 | M26: 23.81 | N26: 25.46 | O26: 22.35 | P26: 25.86 | Q26: 22.45 | R26: 22.29 | S26: 21.92 | T26: 23.06 | U26: 23.48 | V26: 21.8 | W26: 30.84 | X26: 29.62 | Y26: 20.05 | Z26: 24 | AA26: 25.53 | AB26: 23.97 | AC26: 32.4 | AD26: 21.48 | AE26: 27.39 | AF26: 21.3
... A31: ENCARGOS COMPLEMENTARES | B31: 37371 | C31: TRANSPORTE - HORISTA (COLETADO CAIXA - ENCARGOS COMPLEMENTARES) | D31: H | E31: C | F31: 0.27 | G31: 0.48 | H31: 1.67 | I31: 0.38 | J31: 0.88 | K31: 1.09 | L31: 1.52 | M31: 0.66 | N31: 0.55 | O31: 0.51 | P31: 0.9 | Q31: 1.04 | R31: 0.7 | S31: 1.19 | T31: 0.78 | U31: 0.5 | V31: 0.48 | W31: 0.79 | X31: 1.72 | Y31: 0.73 | Z31: 0.08 | AA31: 0.85 | AB31: 1.02 | AC31: 0.98 | AD31: 0.63 | AE31: 1.07 | AF31: 0.7

Sheet ICD
A1: SINAPI - Sistema Nacional de Pesquisa de Custos e Índices da Construção Civil
A2: RELATÓRIO DE PREÇOS DE INSUMOS - ENCARGOS SOCIAIS COM DESONERAÇÃO
A3: Mês de Referência: | B3: 08/2026 | E3: Encargos sociais sobre a mão de obra:
A4: Data de emissão: | B4: 11/09/2026 | E4: (COM DESONERAÇÃO) | F4: AC | G4: AL | H4: AM | I4: AP | J4: BA | K4: CE | L4: DF | M4: ES | N4: GO | O4: MA | P4: MG | Q4: MS | R4: MT | S4: PA | T4: PB | U4: PE | V4: PI | W4: PR | X4: RJ | Y4: RN | Z4: RO | AA4: RR | AB4: RS | AC4: SC | AD4: SE | AE4: SP | AF4: TO
E5: Localidade | F5: RIO BRANCO | G5: MACEIO | H5: MANAUS | I5: MACAPA | J5: SALVADOR | K5: FORTALEZA | L5: BRASILIA | M5: VITORIA | N5: GOIANIA | O5: SAO LUIS | P5: BELO HORIZONTE | Q5: CAMPO GRANDE | R5: CUIABA | S5: BELEM | T5: JOAO PESSOA | U5: RECIFE | V5: TERESINA | W5: CURITIBA | X5: RIO DE JANEIRO | Y5: NATAL | Z5: PORTO VELHO | AA5: BOA VISTA | AB5: PORTO ALEGRE | AC5: FLORIANOPOLIS | AD5: ARACAJU | AE5: SAO PAULO | AF5: PALMAS
A6: Origem de preço: | B6: C = COLETADO | C6: CR = COEFICIENTE DE REPRESENTATIVIDADE | E6: Horista | F6: 0.9688 | G6: 1.0013 | H6: 0.9835 | I6: 0.9923 | J6: 1.017 | K6: 0.9971 | L6: 0.9463 | M6: 1.0222 | N6: 0.9322 | O6: 0.9831 | P6: 1.0033 | Q6: 0.9956 | R6: 0.9089 | S6: 1.0326 | T6: 1.0206 | U6: 0.9883 | V6: 0.9796 | W6: 1.0025 | X6: 0.9688 | Y6: 1.0077 | Z6: 0.9961 | AA6: 0.9885 | AB6: 0.9612 | AC6: 0.9838 | AD6: 0.9588 | AE6: 0.9909 | AF6: 0.9923
A7: Preço em branco para determinado estado significa que não houve coleta mínima de preços no mês de referência | E7: Mensalista | F7: 0.5653 | G7: 0.5859 | H7: 0.582 | I7: 0.5746 | J7: 0.6013 | K7: 0.5974 | L7: 0.5745 | M7: 0.6106 | N7: 0.5747 | O7: 0.5866 | P7: 0.6106 | Q7: 0.5874 | R7: 0.5603 | S7: 0.5998 | T7: 0.5991 | U7: 0.581 | V7: 0.5891 | W7: 0.5965 | X7: 0.572 | Y7: 0.5955 | Z7: 0.5792 | AA7: 0.5772 | AB7: 0.5667 | AC7: 0.5822 | AD7: 0.5718 | AE7: 0.5851 | AF7: 0.592
A9: Acessar Fichas de Especificação Técnico dos Insumos | E9: Preços Medianos (R$):
A10: Classificação | B10: Código do Insumo | C10: Descrição do Insumo | D10: Unidade | E10: Origem de Preço | F10: AC | G10: AL | H10: AM | I10: AP | J10: BA | K10: CE | L10: DF | M10: ES | N10: GO | O10: MA | P10: MG | Q10: MS | R10: MT | S10: PA | T10: PB | U10: PE | V10: PI | W10: PR | X10: RJ | Y10: RN | Z10: RO | AA10: RR | AB10: RS | AC10: SC | AD10: SE | AE10: SP | AF10: TO
A11: ENCARGOS COMPLEMENTARES | B11: 37370 | C11: ALIMENTACAO - HORISTA (COLETADO CAIXA - ENCARGOS COMPLEMENTARES) | D11: H | E11: C | F11: 3.4 | G11: 2.68 | H11: 5.58 | I11: 0.66 | J11: 5 | K11: 4.15 | L11: 4.29 | M11: 7.63 | N11: 3.61 | O11: 2.2 | P11: 2.41 | Q11: 1.73 | R11: 2.9 | S11: 5.15 | T11: 1.82 | U11: 3.06 | V11: 2.49 | W11: 5.96 | X11: 4.78 | Y11: 4.93 | Z11: 3.76 | AA11: 3.52 | AB11: 1.82 | AC11: 0.01 | AD11: 2.96 | AE11: 4.48 | AF11: 2.39
A12: MATERIAL | B12: 370 | C12: AREIA MEDIA - POSTO JAZIDA/FORNECEDOR (RETIRADO NA JAZIDA, SEM TRANSPORTE) | D12: M3 | E12: CR | F12: 144.38 | G12: 120 | H12: 105 | I12: 150 | J12: 139 | K12: 140 | L12: 245.64 | M12: 95 | N12: 222.45 | O12: 150 | P12: 165 | Q12: 82 | R12: 130 | S12: 120 | T12: 140 | U12: 140 | V12: 96.25 | W12: 119.76 | X12: 105 | Y12: 130 | Z12: 180 | AA12: 70 | AB12: 102 | AC12: 148 | AD12: 115 | AE12: 92 | AF12: 157.85
A13: MATERIAL | B13: 34353 | C13: ARGAMASSA COLANTE AC II | D13: KG | E13: CR | F13: 2.66 | G13: 1.86 | H13: 2.36 | I13: 2.1 | J13: 1.69 | K13: 2.21 | L13: 1.24 | M13: 1.39 | N13: 1.58 | O13: 1.63 | P13: 1.3 | Q13: 1.76 | R13: 2.29 | S13: 1.67 | T13: 1.56 | U13: 2.04 | V13: 1.45 | W13: 1.52 | X13: 1.47 | Y13: 1.76 | Z13: 2.04 | AA13: 3.25 | AB13: 1.45 | AC13: 1.39 | AD13: 1.86 | AE13: 1.3 | AF13: 1.58
A14: EQUIPAMENTO (AQUISIÇÃO) | B14: 10535 | C14: BETONEIRA, CAPACIDADE NOMINAL 400 L, CAPACIDADE DE MISTURA 280 L, MOTOR ELETRICO TRIFASICO 220/380 V, POTENCIA 2 CV, SEM CARREGADOR | D14: UN | E14: C | F14: 5749 | G14: 4800 | H14: 5214.65 | I14: 5950 | J14: 5615 | K14: 5809 | L14: 5200 | M14: 5265 | N14: 5800 | O14: 6043.35 | P14: 6447.5 | Q14: 4990 | R14: 5798.6 | S14: 5999.95 | U14: 5439 | V14: 6880.24 | W14: 5518.25 | X14: 5380 | Y14: 5200 | Z14: 6214 | AA14: 5445 | AB14: 4799.9 | AC14: 5290.68 | AE14: 5590 | AF14: 5685.01
A15: MATERIAL | B15: 1106 | C15: CAL HIDRATADA CH-I PARA ARGAMASSAS | D15: KG | E15: C | F15: 2.64 | G15: 1.25 | H15: 1.19 | I15: 1.34 | J15: 1.72 | K15: 1.34 | L15: 1.58 | M15: 1.56 | N15: 1.35 | O15: 1.34 | P15: 1.33 | Q15: 1.3 | R15: 1.25 | S15: 1.34 | T15: 1.25 | U15: 1.8 | V15: 1.34 | W15: 0.83 | X15: 1.36 | Y15: 0.69 | Z15: 1.61 | AA15: 1.34 | AB15: 1.06 | AC15: 0.99 | AD15: 1.4 | AE15: 1.1 | AF15: 1.6
A16: MATERIAL | B16: 1379 | C16: CIMENTO PORTLAND COMPOSTO CP II-32 | D16: KG | E16: C | F16: 1.38 | G16: 0.96 | H16: 1.03 | I16: 1.14 | J16: 1.06 | K16: 0.84 | L16: 0.78 | M16: 0.74 | N16: 0.84 | O16: 1.11 | P16: 0.78 | Q16: 0.9 | R16: 1.05 | S16: 1.08 | T16: 0.88 | U16: 0.91 | V16: 1.14 | W16: 0.79 | X16: 0.68 | Y16: 0.88 | Z16: 1.3 | AA16: 1.67 | AB16: 0.91 | AC16: 0.9 | AD16: 0.94 | AE16: 0.7 | AF16: 1
A17: ESPECIAIS | B17: 2705 | C17: ENERGIA ELETRICA ATE 2000 KWH INDUSTRIAL, SEM DEMANDA | D17: KWH | E17: CR | F17: 1.3 | G17: 1.11 | H17: 0.98 | I17: 1.07 | J17: 1.14 | K17: 0.99 | L17: 0.8 | M17: 1.01 | N17: 1.18 | O17: 1.09 | P17: 1.16 | Q17: 1.28 | R17: 1.17 | S17: 1.22 | T17: 0.86 | U17: 1.03 | V17: 1.1 | W17: 0.85 | X17: 1.29 | Y17: 1.01 | Z17: 1.6 | AA17: 0.99 | AB17: 1.12 | AC17: 0.89 | AD17: 1 | AE17: 0.87 | AF17: 1.35
A18: ENCARGOS COMPLEMENTARES | B18: 43488 | C18: EPI - FAMILIA OPERADOR ESCAVADEIRA - HORISTA (ENCARGOS COMPLEMENTARES - COLETADO CAIXA) | D18: H | E18: C | F18: 0.91 | G18: 0.91 | H18: 0.92 | I18: 1.09 | J18: 0.89 | K18: 0.94 | L18: 0.79 | M18: 0.8 | N18: 0.71 | O18: 0.83 | P18: 0.9 | Q18: 0.9 | R18: 1.08 | S18: 1.11 | T18: 1.05 | U18: 0.92 | V18: 1.13 | W18: 1.03 | X18: 1.07 | Y18: 0.78 | Z18: 0.98 | AA18: 1.16 | AB18: 1.02 | AC18: 0.97 | AD18: 0.8 | AE18: 0.92 | AF18: 1
A19: ENCARGOS COMPLEMENTARES | B19: 43489 | C19: EPI - FAMILIA PEDREIRO - HORISTA (ENCARGOS COMPLEMENTARES - COLETADO CAIXA) | D19: H | E19: C | F19: 1.46 | G19: 1.45 | H19: 1.46 | I19: 1.74 | J19: 1.41 | K19: 1.5 | L19: 1.26 | M19: 1.28 | N19: 1.13 | O19: 1.32 | P19: 1.43 | Q19: 1.43 | R19: 1.72 | S19: 1.76 | T19: 1.68 | U19: 1.47 | V19: 1.81 | W19: 1.64 | X19: 1.71 | Y19: 1.25 | Z19: 1.56 | AA19: 1.85 | AB19: 1.62 | AC19: 1.55 | AD19: 1.28 | AE19: 1.47 | AF19: 1.6
A20: ENCARGOS COMPLEMENTARES | B20: 43491 | C20: EPI - FAMILIA SERVENTE - HORISTA (ENCARGOS COMPLEMENTARES - COLETADO CAIXA) | D20: H | E20: C | F20: 1.53 | G20: 1.52 | H20: 1.53 | I20: 1.82 | J20: 1.48 | K20: 1.57 | L20: 1.32 | M20: 1.34 | N20: 1.18 | O20: 1.38 | P20: 1.5 | Q20: 1.5 | R20: 1.8 | S20: 1.85 | T20: 1.75 | U20: 1.54 | V20: 1.89 | W20: 1.71 | X20: 1.79 | Y20: 1.31 | Z20: 1.63 | AA20: 1.94 | AB20: 1.7 | AC20: 1.62 | AD20: 1.34 | AE20: 1.54 | AF20: 1.67
A21: ENCARGOS COMPLEMENTARES | B21: 37372 | C21: EXAMES - HORISTA (COLETADO CAIXA - ENCARGOS COMPLEMENTARES) | D21: H | E21: C | F21: 1.32 | G21: 1.4 | H21: 1.29 | I21: 1.3 | J21: 1.49 | K21: 1.48 | L21: 1.31 | M21: 1.62 | N21: 1.58 | O21: 1.36 | P21: 1.57 | Q21: 1.67 | R21: 1.62 | S21: 1.51 | T21: 1.56 | U21: 1.24 | V21: 1.42 | W21: 1.58 | X21: 1.25 | Y21: 1.55 | Z21: 1.52 | AA21: 1.36 | AB21: 1.36 | AC21: 1.65 | AD21: 1.39 | AE21: 1.43 | AF21: 1.59
A22: ENCARGOS COMPLEMENTARES | B22: 43464 | C22: FERRAMENTAS - FAMILIA OPERADOR ESCAVADEIRA - HORISTA (ENCARGOS COMPLEMENTARES - COLETADO CAIXA) | D22: H | E22: C | F22: 0.03 | G22: 0.02 | H22: 0.02 | I22: 0.03 | J22: 0.02 | K22: 0.02 | L22: 0.03 | M22: 0.02 | N22: 0.02 | O22: 0.03 | P22: 0.03 | Q22: 0.02 | R22: 0.03 | S22: 0.03 | T22: 0.03 | U22: 0.02 | V22: 0.05 | W22: 0.02 | X22: 0.02 | Y22: 0.03 | Z22: 0.03 | AA22: 0.03 | AB22: 0.03 | AC22: 0.03 | AD22: 0.02 | AE22: 0.02 | AF22: 0.03
A23: ENCARGOS COMPLEMENTARES | B23: 43465 | C23: FERRAMENTAS - FAMILIA PEDREIRO - HORISTA (ENCARGOS COMPLEMENTARES - COLETADO CAIXA) | D23: H | E23: C | F23: 0.7 | G23: 0.6 | H23: 0.57 | I23: 0.65 | J23: 0.59 | K23: 0.6 | L23: 0.71 | M23: 0.68 | N23: 0.62 | O23: 0.73 | P23: 0.8 | Q23: 0.81 | R23: 0.74 | S23: 0.65 | T23: 0.63 | U23: 0.6 | V23: 0.9 | W23: 0.6 | X23: 0.64 | Y23: 0.66 | Z23: 0.74 | AA23: 0.63 | AB23: 0.71 | AC23: 0.72 | AD23: 0.61 | AE23: 0.73 | AF23: 0.83
A24: ENCARGOS COMPLEMENTARES | B24: 43467 | C24: FERRAMENTAS - FAMILIA SERVENTE - HORISTA (ENCARGOS COMPLEMENTARES - COLETADO CAIXA) | D24: H | E24: C | F24: 0.6 | G24: 0.48 | H24: 0.57 | I24: 0.61 | J24: 0.47 | K24: 0.57 | L24: 0.58 | M24: 0.57 | N24: 0.56 | O24: 0.58 | P24: 0.67 | Q24: 0.49 | R24: 0.6 | S24: 0.56 | T24: 0.58 | U24: 0.5 | V24: 1 | W24: 0.42 | X24: 0.56 | Y24: 0.62 | Z24: 0.63 | AA24: 0.64 | AB24: 0.57 | AC24: 0.6 | AD24: 0.49 | AE24: 0.57 | AF24: 0.69
A25: MAO DE OBRA | B25: 37666 | C25: OPERADOR DE BETONEIRA ESTACIONARIA / MISTURADOR (HORISTA) | D25: H | E25: CR | F25: 16.41 | G25: 14.4 | H25: 23.76 | I25: 14.16 | J25: 33.86 | K25: 21.08 | L25: 18.48 | M25: 22.62 | N25: 13.91 | O25: 25.04 | P25: 22.19 | Q25: 21.17 | R25: 16.03 | S25: 19.1 | T25: 15.39 | U25: 16.2 | V25: 21.32 | W25: 26.13 | X25: 23.13 | Y25: 19.35 | Z25: 19.04 | AA25: 15.41 | AB25: 24.31 | AC25: 30.96 | AD25: 19.21 | AE25: 24.72 | AF25: 15
A26: MAO DE OBRA | B26: 4750 | C26: PEDREIRO (HORISTA) | D26: H | E26: C | F26: 23.44 | G26: 18.77 | H26: 21.38 | I26: 20.71 | J26: 23.86 | K26: 21.62 | L26: 22.42 | M26: 22.06 | N26: 23.68 | O26: 20.7 | P26: 23.95 | Q26: 20.77 | R26: 20.73 | S26: 20.3 | T26: 21.35 | U26: 21.75 | V26: 20.19 | W26: 28.55 | X26: 27.44 | Y26: 18.57 | Z26: 22.21 | AA26: 23.64 | AB26: 22.18 | AC26: 29.97 | AD26: 19.9 | AE26: 25.36 | AF26: 19.72
... A31: ENCARGOS COMPLEMENTARES | B31: 37371 | C31: TRANSPORTE - HORISTA (COLETADO CAIXA - ENCARGOS COMPLEMENTARES) | D31: H | E31: C | F31: 0.27 | G31: 0.48 | H31: 1.67 | I31: 0.38 | J31: 0.88 | K31: 1.09 | L31: 1.52 | M31: 0.66 | N31: 0.55 | O31: 0.51 | P31: 0.9 | Q31: 1.04 | R31: 0.7 | S31: 1.19 | T31: 0.78 | U31: 0.5 | V31: 0.48 | W31: 0.79 | X31: 1.72 | Y31: 0.73 | Z31: 0.08 | AA31: 0.85 | AB31: 1.02 | AC31: 0.98 | AD31: 0.63 | AE31: 1.07 | AF31: 0.7

Sheet ISE
A1: SINAPI - Sistema Nacional de Pesquisa de Custos e Índices da Construção Civil
A2: RELATÓRIO DE PREÇOS DE INSUMOS - SEM ENCARGOS SOCIAIS
A3: Mês de Referência: | B3: 08/2026
A4: Data de emissão: | B4: 11/09/2026
A6: Origem de preço: | B6: C = COLETADO | C6: CR = COEFICIENTE DE REPRESENTATIVIDADE
A7: Preço em branco para determinado estado significa que não houve coleta mínima de preços no mês de referência
A9: Acessar Fichas de Especificação Técnico dos Insumos | E9: Preços Medianos (R$):
A10: Classificação | B10: Código do Insumo | C10: Descrição do Insumo | D10: Unidade | E10: Origem de Preço | F10: AC | G10: AL | H10: AM | I10: AP | J10: BA | K10: CE | L10: DF | M10: ES | N10: GO | O10: MA | P10: MG | Q10: MS | R10: MT | S10: PA | T10: PB | U10: PE | V10: PI | W10: PR | X10: RJ | Y10: RN | Z10: RO | AA10: RR | AB10: RS | AC10: SC | AD10: SE | AE10: SP | AF10: TO
A11: ENCARGOS COMPLEMENTARES | B11: 37370 | C11: ALIMENTACAO - HORISTA (COLETADO CAIXA - ENCARGOS COMPLEMENTARES) | D11: H | E11: C | F11: 3.4 | G11: 2.68 | H11: 5.58 | I11: 0.66 | J11: 5 | K11: 4.15 | L11: 4.29 | M11: 7.63 | N11: 3.61 | O11: 2.2 | P11: 2.41 | Q11: 1.73 | R11: 2.9 | S11: 5.15 | T11: 1.82 | U11: 3.06 | V11: 2.49 | W11: 5.96 | X11: 4.78 | Y11: 4.93 | Z11: 3.76 | AA11: 3.52 | AB11: 1.82 | AC11: 0.01 | AD11: 2.96 | AE11: 4.48 | AF11: 2.39
A12: MATERIAL | B12: 370 | C12: AREIA MEDIA - POSTO JAZIDA/FORNECEDOR (RETIRADO NA JAZIDA, SEM TRANSPORTE) | D12: M3 | E12: CR | F12: 144.38 | G12: 120 | H12: 105 | I12: 150 | J12: 139 | K12: 140 | L12: 245.64 | M12: 95 | N12: 222.45 | O12: 150 | P12: 165 | Q12: 82 | R12: 130 | S12: 120 | T12: 140 | U12: 140 | V12: 96.25 | W12: 119.76 | X12: 105 | Y12: 130 | Z12: 180 | AA12: 70 | AB12: 102 | AC12: 148 | AD12: 115 | AE12: 92 | AF12: 157.85
A13: MATERIAL | B13: 34353 | C13: ARGAMASSA COLANTE AC II | D13: KG | E13: CR | F13: 2.66 | G13: 1.86 | H13: 2.36 | I13: 2.1 | J13: 1.69 | K13: 2.21 | L13: 1.24 | M13: 1.39 | N13: 1.58 | O13: 1.63 | P13: 1.3 | Q13: 1.76 | R13: 2.29 | S13: 1.67 | T13: 1.56 | U13: 2.04 | V13: 1.45 | W13: 1.52 | X13: 1.47 | Y13: 1.76 | Z13: 2.04 | AA13: 3.25 | AB13: 1.45 | AC13: 1.39 | AD13: 1.86 | AE13: 1.3 | AF13: 1.58
A14: EQUIPAMENTO (AQUISIÇÃO) | B14: 10535 | C14: BETONEIRA, CAPACIDADE NOMINAL 400 L, CAPACIDADE DE MISTURA 280 L, MOTOR ELETRICO TRIFASICO 220/380 V, POTENCIA 2 CV, SEM CARREGADOR | D14: UN | E14: C | F14: 5749 | G14: 4800 | H14: 5214.65 | I14: 5950 | J14: 5615 | K14: 5809 | L14: 5200 | M14: 5265 | N14: 5800 | O14: 6043.35 | P14: 6447.5 | Q14: 4990 | R14: 5798.6 | S14: 5999.95 | U14: 5439 | V14: 6880.24 | W14: 5518.25 | X14: 5380 | Y14: 5200 | Z14: 6214 | AA14: 5445 | AB14: 4799.9 | AC14: 5290.68 | AE14: 5590 | AF14: 5685.01
A15: MATERIAL | B15: 1106 | C15: CAL HIDRATADA CH-I PARA ARGAMASSAS | D15: KG | E15: C | F15: 2.64 | G15: 1.25 | H15: 1.19 | I15: 1.34 | J15: 1.72 | K15: 1.34 | L15: 1.58 | M15: 1.56 | N15: 1.35 | O15: 1.34 | P15: 1.33 | Q15: 1.3 | R15: 1.25 | S15: 1.34 | T15: 1.25 | U15: 1.8 | V15: 1.34 | W15: 0.83 | X15: 1.36 | Y15: 0.69 | Z15: 1.61 | AA15: 1.34 | AB15: 1.06 | AC15: 0.99 | AD15: 1.4 | AE15: 1.1 | AF15: 1.6
A16: MATERIAL | B16: 1379 | C16: CIMENTO PORTLAND COMPOSTO CP II-32 | D16: KG | E16: C | F16: 1.38 | G16: 0.96 | H16: 1.03 | I16: 1.14 | J16: 1.06 | K16: 0.84 | L16: 0.78 | M16: 0.74 | N16: 0.84 | O16: 1.11 | P16: 0.78 | Q16: 0.9 | R16: 1.05 | S16: 1.08 | T16: 0.88 | U16: 0.91 | V16: 1.14 | W16: 0.79 | X16: 0.68 | Y16: 0.88 | Z16: 1.3 | AA16: 1.67 | AB16: 0.91 | AC16: 0.9 | AD16: 0.94 | AE16: 0.7 | AF16: 1
A17: ESPECIAIS | B17: 2705 | C17: ENERGIA ELETRICA ATE 2000 KWH INDUSTRIAL, SEM DEMANDA | D17: KWH | E17: CR | F17: 1.3 | G17: 1.11 | H17: 0.98 | I17: 1.07 | J17: 1.14 | K17: 0.99 | L17: 0.8 | M17: 1.01 | N17: 1.18 | O17: 1.09 | P17: 1.16 | Q17: 1.28 | R17: 1.17 | S17: 1.22 | T17: 0.86 | U17: 1.03 | V17: 1.1 | W17: 0.85 | X17: 1.29 | Y17: 1.01 | Z17: 1.6 | AA17: 0.99 | AB17: 1.12 | AC17: 0.89 | AD17: 1 | AE17: 0.87 | AF17: 1.35
A18: ENCARGOS COMPLEMENTARES | B18: 43488 | C18: EPI - FAMILIA OPERADOR ESCAVADEIRA - HORISTA (ENCARGOS COMPLEMENTARES - COLETADO CAIXA) | D18: H | E18: C | F18: 0.91 | G18: 0.91 | H18: 0.92 | I18: 1.09 | J18: 0.89 | K18: 0.94 | L18: 0.79 | M18: 0.8 | N18: 0.71 | O18: 0.83 | P18: 0.9 | Q18: 0.9 | R18: 1.08 | S18: 1.11 | T18: 1.05 | U18: 0.92 | V18: 1.13 | W18: 1.03 | X18: 1.07 | Y18: 0.78 | Z18: 0.98 | AA18: 1.16 | AB18: 1.02 | AC18: 0.97 | AD18: 0.8 | AE18: 0.92 | AF18: 1
A19: ENCARGOS COMPLEMENTARES | B19: 43489 | C19: EPI - FAMILIA PEDREIRO - HORISTA (ENCARGOS COMPLEMENTARES - COLETADO CAIXA) | D19: H | E19: C | F19: 1.46 | G19: 1.45 | H19: 1.46 | I19: 1.74 | J19: 1.41 | K19: 1.5 | L19: 1.26 | M19: 1.28 | N19: 1.13 | O19: 1.32 | P19: 1.43 | Q19: 1.43 | R19: 1.72 | S19: 1.76 | T19: 1.68 | U19: 1.47 | V19: 1.81 | W19: 1.64 | X19: 1.71 | Y19: 1.25 | Z19: 1.56 | AA19: 1.85 | AB19: 1.62 | AC19: 1.55 | AD19: 1.28 | AE19: 1.47 | AF19: 1.6
A20: ENCARGOS COMPLEMENTARES | B20: 43491 | C20: EPI - FAMILIA SERVENTE - HORISTA (ENCARGOS COMPLEMENTARES - COLETADO CAIXA) | D20: H | E20: C | F20: 1.53 | G20: 1.52 | H20: 1.53 | I20: 1.82 | J20: 1.48 | K20: 1.57 | L20: 1.32 | M20: 1.34 | N20: 1.18 | O20: 1.38 | P20: 1.5 | Q20: 1.5 | R20: 1.8 | S20: 1.85 | T20: 1.75 | U20: 1.54 | V20: 1.89 | W20: 1.71 | X20: 1.79 | Y20: 1.31 | Z20: 1.63 | AA20: 1.94 | AB20: 1.7 | AC20: 1.62 | AD20: 1.34 | AE20: 1.54 | AF20: 1.67
A21: ENCARGOS COMPLEMENTARES | B21: 37372 | C21: EXAMES - HORISTA (COLETADO CAIXA - ENCARGOS COMPLEMENTARES) | D21: H | E21: C | F21: 1.32 | G21: 1.4 | H21: 1.29 | I21: 1.3 | J21: 1.49 | K21: 1.48 | L21: 1.31 | M21: 1.62 | N21: 1.58 | O21: 1.36 | P21: 1.57 | Q21: 1.67 | R21: 1.62 | S21: 1.51 | T21: 1.56 | U21: 1.24 | V21: 1.42 | W21: 1.58 | X21: 1.25 | Y21: 1.55 | Z21: 1.52 | AA21: 1.36 | AB21: 1.36 | AC21: 1.65 | AD21: 1.39 | AE21: 1.43 | AF21: 1.59
A22: ENCARGOS COMPLEMENTARES | B22: 43464 | C22: FERRAMENTAS - FAMILIA OPERADOR ESCAVADEIRA - HORISTA (ENCARGOS COMPLEMENTARES - COLETADO CAIXA) | D22: H | E22: C | F22: 0.03 | G22: 0.02 | H22: 0.02 | I22: 0.03 | J22: 0.02 | K22: 0.02 | L22: 0.03 | M22: 0.02 | N22: 0.02 | O22: 0.03 | P22: 0.03 | Q22: 0.02 | R22: 0.03 | S22: 0.03 | T22: 0.03 | U22: 0.02 | V22: 0.05 | W22: 0.02 | X22: 0.02 | Y22: 0.03 | Z22: 0.03 | AA22: 0.03 | AB22: 0.03 | AC22: 0.03 | AD22: 0.02 | AE22: 0.02 | AF22: 0.03
A23: ENCARGOS COMPLEMENTARES | B23: 43465 | C23: FERRAMENTAS - FAMILIA PEDREIRO - HORISTA (ENCARGOS COMPLEMENTARES - COLETADO CAIXA) | D23: H | E23: C | F23: 0.7 | G23: 0.6 | H23: 0.57 | I23: 0.65 | J23: 0.59 | K23: 0.6 | L23: 0.71 | M23: 0.68 | N23: 0.62 | O23: 0.73 | P23: 0.8 | Q23: 0.81 | R23: 0.74 | S23: 0.65 | T23: 0.63 | U23: 0.6 | V23: 0.9 | W23: 0.6 | X23: 0.64 | Y23: 0.66 | Z23: 0.74 | AA23: 0.63 | AB23: 0.71 | AC23: 0.72 | AD23: 0.61 | AE23: 0.73 | AF23: 0.83
A24: ENCARGOS COMPLEMENTARES | B24: 43467 | C24: FERRAMENTAS - FAMILIA SERVENTE - HORISTA (ENCARGOS COMPLEMENTARES - COLETADO CAIXA) | D24: H | E24: C | F24: 0.6 | G24: 0.48 | H24: 0.57 | I24: 0.61 | J24: 0.47 | K24: 0.57 | L24: 0.58 | M24: 0.57 | N24: 0.56 | O24: 0.58 | P24: 0.67 | Q24: 0.49 | R24: 0.6 | S24: 0.56 | T24: 0.58 | U24: 0.5 | V24: 1 | W24: 0.42 | X24: 0.56 | Y24: 0.62 | Z24: 0.63 | AA24: 0.64 | AB24: 0.57 | AC24: 0.6 | AD24: 0.49 | AE24: 0.57 | AF24: 0.69
A25: MAO DE OBRA | B25: 37666 | C25: OPERADOR DE BETONEIRA ESTACIONARIA / MISTURADOR (HORISTA) | D25: H | E25: CR | F25: 8.34 | G25: 7.2 | H25: 11.98 | I25: 7.11 | J25: 16.79 | K25: 10.56 | L25: 9.5 | M25: 11.19 | N25: 7.2 | O25: 12.63 | P25: 11.08 | Q25: 10.61 | R25: 8.4 | S25: 9.4 | T25: 7.62 | U25: 8.15 | V25: 10.77 | W25: 13.05 | X25: 11.75 | Y25: 9.64 | Z25: 9.54 | AA25: 7.75 | AB25: 12.4 | AC25: 15.61 | AD25: 9.81 | AE25: 12.42 | AF25: 7.53
A26: MAO DE OBRA | B26: 4750 | C26: PEDREIRO (HORISTA) | D26: H | E26: C | F26: 11.91 | G26: 9.38 | H26: 10.78 | I26: 10.4 | J26: 11.83 | K26: 10.83 | L26: 11.52 | M26: 10.91 | N26: 12.26 | O26: 10.44 | P26: 11.96 | Q26: 10.41 | R26: 10.86 | S26: 9.99 | T26: 10.57 | U26: 10.94 | V26: 10.2 | W26: 14.26 | X26: 13.94 | Y26: 9.25 | Z26: 11.13 | AA26: 11.89 | AB26: 11.31 | AC26: 15.11 | AD26: 10.16 | AE26: 12.74 | AF26: 9.9
... A31: ENCARGOS COMPLEMENTARES | B31: 37371 | C31: TRANSPORTE - HORISTA (COLETADO CAIXA - ENCARGOS COMPLEMENTARES) | D31: H | E31: C | F31: 0.27 | G31: 0.48 | H31: 1.67 | I31: 0.38 | J31: 0.88 | K31: 1.09 | L31: 1.52 | M31: 0.66 | N31: 0.55 | O31: 0.51 | P31: 0.9 | Q31: 1.04 | R31: 0.7 | S31: 1.19 | T31: 0.78 | U31: 0.5 | V31: 0.48 | W31: 0.79 | X31: 1.72 | Y31: 0.73 | Z31: 0.08 | AA31: 0.85 | AB31: 1.02 | AC31: 0.98 | AD31: 0.63 | AE31: 1.07 | AF31: 0.7

Sheet CSD
A1: SINAPI - Sistema Nacional de Pesquisa de Custos e Índices da Construção Civil
A2: RELATÓRIO DE CUSTOS DE COMPOSIÇÕES - ENCARGOS SOCIAIS SEM DESONERAÇÃO
A3: Mês de Referência: | B3: 08/2026 | D3: Encargos sociais sobre a mão de obra:
A4: Data de emissão: | B4: 11/09/2026 | D4: (SEM DESONERAÇÃO) | E4: AC | G4: AL | I4: AM | K4: AP | M4: BA | O4: CE | Q4: DF | S4: ES | U4: GO | W4: MA | Y4: MG | AA4: MS | AC4: MT | AE4: PA | AG4: PB | AI4: PE | AK4: PI | AM4: PR | AO4: RJ | AQ4: RN | AS4: RO | AU4: RR | AW4: RS | AY4: SC | BA4: SE | BC4: SP | BE4: TO
D5: Localidade | E5: RIO BRANCO | G5: MACEIO | I5: MANAUS | K5: MACAPA | M5: SALVADOR | O5: FORTALEZA | Q5: BRASILIA | S5: VITORIA | U5: GOIANIA | W5: SAO LUIS | Y5: BELO HORIZONTE | AA5: CAMPO GRANDE | AC5: CUIABA | AE5: BELEM | AG5: JOAO PESSOA | AI5: RECIFE | AK5: TERESINA | AM5: CURITIBA | AO5: RIO DE JANEIRO | AQ5: NATAL | AS5: PORTO VELHO | AU5: BOA VISTA | AW5: PORTO ALEGRE | AY5: FLORIANOPOLIS | BA5: ARACAJU | BC5: SAO PAULO | BE5: PALMAS
A6: Observação: | B6: %AS (porcentagem Atribuído São Paulo) corresponde a porcentagem do custo total da | D6: Horista | E6: 1.1261 | G6: 1.1612 | I6: 1.1416 | K6: 1.1518 | M6: 1.1773 | O6: 1.1561 | Q6: 1.1008 | S6: 1.183 | U6: 1.0772 | W6: 1.1411 | Y6: 1.1623 | AA6: 1.1571 | AC6: 1.0533 | AE6: 1.1942 | AG6: 1.1819 | AI6: 1.1463 | AK6: 1.1378 | AM6: 1.1628 | AO6: 1.1249 | AQ6: 1.1683 | AS6: 1.1571 | AU6: 1.1479 | AW6: 1.1195 | AY6: 1.1447 | BA6: 1.1151 | BC6: 1.1501 | BE6: 1.1523
B7: composição que foi obtida utilizando preços de insumos de São Paulo por indisponibilidade | D7: Mensalista | E7: 0.6903 | G7: 0.7125 | I7: 0.708 | K7: 0.7006 | M7: 0.7285 | O7: 0.7246 | Q7: 0.6994 | S7: 0.7385 | U7: 0.6928 | W7: 0.713 | Y7: 0.7383 | AA7: 0.7157 | AC7: 0.6783 | AE7: 0.727 | AG7: 0.7266 | AI7: 0.7067 | AK7: 0.7159 | AM7: 0.7242 | AO7: 0.6966 | AQ7: 0.7229 | AS7: 0.7065 | AU7: 0.7035 | AW7: 0.6929 | AY7: 0.7103 | BA7: 0.6972 | BC7: 0.7118 | BE7: 0.7198
B8: dos preços de insumos necessários à composição no estado em questão. Custo zerado (hífen)
B9: indica que pelo menos um dos itens da composição não tem custo/preço. | E9: AC | G9: AL | I9: AM | K9: AP | M9: BA | O9: CE | Q9: DF | S9: ES | U9: GO | W9: MA | Y9: MG | AA9: MS | AC9: MT | AE9: PA | AG9: PB | AI9: PE | AK9: PI | AM9: PR | AO9: RJ | AQ9: RN | AS9: RO | AU9: RR | AW9: RS | AY9: SC | BA9: SE | BC9: SP | BE9: TO
A10: Grupo | B10: Código da Composição | C10: Descrição | D10: Unidade | E10: Custo (R$) | F10: %AS | G10: Custo (R$) | H10: %AS | I10: Custo (R$) | J10: %AS | K10: Custo (R$) | L10: %AS | M10: Custo (R$) | N10: %AS | O10: Custo (R$) | P10: %AS | Q10: Custo (R$) | R10: %AS | S10: Custo (R$) | T10: %AS | U10: Custo (R$) | V10: %AS | W10: Custo (R$) | X10: %AS | Y10: Custo (R$) | Z10: %AS | AA10: Custo (R$) | AB10: %AS | AC10: Custo (R$) | AD10: %AS | AE10: Custo (R$) | AF10: %AS | AG10: Custo (R$) | AH10: %AS | AI10: Custo (R$) | AJ10: %AS | AK10: Custo (R$) | AL10: %AS | AM10: Custo (R$) | AN10: %AS | AO10: Custo (R$) | AP10: %AS | AQ10: Custo (R$) | AR10: %AS | AS10: Custo (R$) | AT10: %AS | AU10: Custo (R$) | AV10: %AS | AW10: Custo (R$) | AX10: %AS | AY10: Custo (R$) | AZ10: %AS | BA10: Custo (R$) | BB10: %AS | BC10: Custo (R$) | BD10: %AS | BE10: Custo (R$) | BF10: %AS
A11: Acessibilidade | B11: =HYPERLINK("#"&CELL("address",OFFSET(Analítico!$B$1,MATCH(104658,Analítico!$B:$B,0)-1,3)),104658) | C11: PISO PODOTÁTIL DE ALERTA OU DIRECIONAL, DE CONCRETO, ASSENTADO SOBRE ARGAMASSA. AF_03/2024 | D11: M2 | E11: 279.44 | F11: 0 | G11: 163.64 | H11: 0 | I11: 228.39 | J11: 0 | K11: 200.2 | L11: 0 | M11: 171.51 | N11: 0 | O11: 172.77 | P11: 0 | Q11: 185.84 | R11: 0 | S11: 188.15 | T11: 0 | U11: 191.09 | V11: 0 | W11: 176.23 | X11: 0 | Y11: 164.81 | Z11: 0 | AA11: 177.02 | AB11: 0 | AC11: 221.04 | AD11: 0 | AE11: 188.81 | AF11: 0 | AG11: 152.22 | AH11: 0 | AI11: 166.81 | AJ11: 0 | AK11: 154.27 | AL11: 0 | AM11: 158.33 | AN11: 0 | AO11: 190.33 | AP11: 0 | AQ11: 167.72 | AR11: 0 | AS11: 224.12 | AT11: 0 | AU11: 275.56 | AV11: 0 | AW11: 156.97 | AX11: 0 | AY11: 161.29 | AZ11: 0 | BA11: 181.54 | BB11: 0 | BC11: 208 | BD11: 0 | BE11: 204.46 | BF11: 0
A12: Acessibilidade | B12: =HYPERLINK("#"&CELL("address",OFFSET(Analítico!$B$1,MATCH(105006,Analítico!$B:$B,0)-1,3)),105006) | C12: RAMPA DE ACESSIBILIDADE EM CONCRETO PRÉ MOLDADO, EM CALÇADA NOVA COM LARGURA MAIOR OU IGUAL À 3,00 M, FCK 25MPA, COM PISO PODOTÁTIL. AF_03/2024 | D12: UN | E12: 0 | G12: 0 | I12: 0 | K12: 0 | M12: 0 | O12: 0 | Q12: 0 | S12: 0 | U12: 0 | W12: 0 | Y12: 0 | AA12: 0 | AC12: 0 | AE12: 0 | AG12: 0 | AI12: 0 | AK12: 0 | AM12: 0 | AO12: 0 | AQ12: 0 | AS12: 0 | AU12: 0 | AW12: 0 | AY12: 0 | BA12: 0 | BC12: 0 | BE12: 0
A13: Argamassas | B13: =HYPERLINK("#"&CELL("address",OFFSET(Analítico!$B$1,MATCH(87286,Analítico!$B:$B,0)-1,3)),87286) | C13: ARGAMASSA TRAÇO 1:1:6 (EM VOLUME DE CIMENTO, CAL E AREIA MÉDIA ÚMIDA) PARA EMBOÇO/MASSA ÚNICA/ASSENTAMENTO DE ALVENARIA DE VEDAÇÃO, PREPARO MECÂNICO COM BETONEIRA ATÉ 600 L. AF_07/2026 | D13: M3 | E13: 961.85 | F13: 0 | G13: 650.28 | H13: 0 | I13: 721.7 | J13: 0 | K13: 729.08 | L13: 0 | M13: 883.43 | N13: 0 | O13: 704.58 | P13: 0 | Q13: 823.43 | R13: 0 | S13: 677.85 | T13: 0 | U13: 751.09 | V13: 0 | W13: 794.73 | X13: 0 | Y13: 713.59 | Z13: 0 | AA13: 636.86 | AB13: 0 | AC13: 699.5 | AD13: 0 | AE13: 739.48 | AF13: 0 | AG13: 656.55 | AH13: 0.0043 | AI13: 735.8 | AJ13: 0 | AK13: 722.59 | AL13: 0 | AM13: 648.56 | AN13: 0 | AO13: 643.94 | AP13: 0 | AQ13: 620.07 | AR13: 0 | AS13: 881.97 | AT13: 0 | AU13: 800.15 | AV13: 0 | AW13: 652.62 | AX13: 0 | AY13: 725.56 | AZ13: 0 | BA13: 687.13 | BB13: 0.0041 | BC13: 608.38 | BD13: 0 | BE13: 749.95 | BF13: 0
A14: Argamassas | B14: =HYPERLINK("#"&CELL("address",OFFSET(Analítico!$B$1,MATCH(87307,Analítico!$B:$B,0)-1,3)),87307) | C14: ARGAMASSA TRAÇO 1:6 (EM VOLUME DE CIMENTO E AREIA MÉDIA ÚMIDA) PARA CONTRAPISO, PREPARO MECÂNICO COM BETONEIRA ATÉ 600 L. AF_07/2026 | D14: M3 | E14: 799.79 | F14: 0 | G14: 609.62 | H14: 0 | I14: 682.68 | J14: 0 | K14: 702.37 | L14: 0 | M14: 793.17 | N14: 0 | O14: 647.55 | P14: 0 | Q14: 770.43 | R14: 0 | S14: 571.3 | T14: 0 | U14: 723.81 | V14: 0 | W14: 760.55 | X14: 0 | Y14: 661.73 | Z14: 0 | AA14: 570.49 | AB14: 0 | AC14: 667.86 | AD14: 0 | AE14: 694.05 | AF14: 0 | AG14: 616.26 | AH14: 0.0043 | AI14: 633.95 | AJ14: 0 | AK14: 674.09 | AL14: 0 | AM14: 636.93 | AN14: 0 | AO14: 559.72 | AP14: 0 | AQ14: 638.02 | AR14: 0 | AS14: 842.86 | AT14: 0 | AU14: 784.64 | AV14: 0 | AW14: 619.97 | AX14: 0 | AY14: 713.3 | AZ14: 0 | BA14: 623.9 | BB14: 0.0042 | BC14: 550.91 | BD14: 0 | BE14: 684.21 | BF14: 0
A15: Custos Horários Produtivo e Improdutivo dos Equipamentos | B15: =HYPERLINK("#"&CELL("address",OFFSET(Analítico!$B$1,MATCH(88831,Analítico!$B:$B,0)-1,3)),88831) | C15: BETONEIRA CAPACIDADE NOMINAL DE 400 L, CAPACIDADE DE MISTURA 280 L, MOTOR ELÉTRICO TRIFÁSICO POTÊNCIA DE 2 CV, SEM CARREGADOR - CHI DIURNO. AF_05/2023 | D15: CHI | E15: 0.44 | F15: 0 | G15: 0.37 | H15: 0 | I15: 0.4 | J15: 0 | K15: 0.46 | L15: 0 | M15: 0.43 | N15: 0 | O15: 0.45 | P15: 0 | Q15: 0.4 | R15: 0 | S15: 0.4 | T15: 0 | U15: 0.45 | V15: 0 | W15: 0.46 | X15: 0 | Y15: 0.5 | Z15: 0 | AA15: 0.38 | AB15: 0 | AC15: 0.45 | AD15: 0 | AE15: 0.46 | AF15: 0 | AG15: 0.43 | AH15: 1 | AI15: 0.42 | AJ15: 0 | AK15: 0.54 | AL15: 0 | AM15: 0.43 | AN15: 0 | AO15: 0.41 | AP15: 0 | AQ15: 0.4 | AR15: 0 | AS15: 0.48 | AT15: 0 | AU15: 0.42 | AV15: 0 | AW15: 0.37 | AX15: 0 | AY15: 0.4 | AZ15: 0 | BA15: 0.43 | BB15: 1 | BC15: 0.43 | BD15: 0 | BE15: 0.44 | BF15: 0
A16: Custos Horários Produtivo e Improdutivo dos Equipamentos | B16: =HYPERLINK("#"&CELL("address",OFFSET(Analítico!$B$1,MATCH(88830,Analítico!$B:$B,0)-1,3)),88830) | C16: BETONEIRA CAPACIDADE NOMINAL DE 400 L, CAPACIDADE DE MISTURA 280 L, MOTOR ELÉTRICO TRIFÁSICO POTÊNCIA DE 2 CV, SEM CARREGADOR - CHP DIURNO. AF_05/2023 | D16: CHP | E16: 2.46 | F16: 0 | G16: 2.08 | H16: 0 | I16: 1.98 | J16: 0 | K16: 2.2 | L16: 0 | M16: 2.24 | N16: 0 | O16: 2.08 | P16: 0 | Q16: 1.76 | R16: 0 | S16: 2.02 | T16: 0 | U16: 2.32 | V16: 0 | W16: 2.24 | X16: 0 | Y16: 2.4 | Z16: 0 | AA16: 2.32 | AB16: 0 | AC16: 2.31 | AD16: 0 | AE16: 2.39 | AF16: 0 | AG16: 1.89 | AH16: 0.4339 | AI16: 2.08 | AJ16: 0 | AK16: 2.39 | AL16: 0 | AM16: 1.87 | AN16: 0 | AO16: 2.39 | AP16: 0 | AQ16: 2.02 | AR16: 0 | AS16: 2.91 | AT16: 0 | AU16: 2.03 | AV16: 0 | AW16: 2.1 | AX16: 0 | AY16: 1.88 | AZ16: 0 | BA16: 2.07 | BB16: 0.3961 | BC16: 1.9 | BD16: 0 | BE16: 2.51 | BF16: 0
A17: Depreciação, Juros, Impostos e Seguros, Manutenção e Materiais na Operação dos Equipamentos | B17: =HYPERLINK("#"&CELL("address",OFFSET(Analítico!$B$1,MATCH(88826,Analítico!$B:$B,0)-1,3)),88826) | C17: BETONEIRA CAPACIDADE NOMINAL DE 400 L, CAPACIDADE DE MISTURA 280 L, MOTOR ELÉTRICO TRIFÁSICO POTÊNCIA DE 2 CV, SEM CARREGADOR - DEPRECIAÇÃO. AF_05/2023 | D17: H | E17: 0.36 | F17: 0 | G17: 0.3 | H17: 0 | I17: 0.33 | J17: 0 | K17: 0.38 | L17: 0 | M17: 0.35 | N17: 0 | O17: 0.37 | P17: 0 | Q17: 0.33 | R17: 0 | S17: 0.33 | T17: 0 | U17: 0.37 | V17: 0 | W17: 0.38 | X17: 0 | Y17: 0.41 | Z17: 0 | AA17: 0.31 | AB17: 0 | AC17: 0.37 | AD17: 0 | AE17: 0.38 | AF17: 0 | AG17: 0.35 | AH17: 1 | AI17: 0.34 | AJ17: 0 | AK17: 0.44 | AL17: 0 | AM17: 0.35 | AN17: 0 | AO17: 0.34 | AP17: 0 | AQ17: 0.33 | AR17: 0 | AS17: 0.39 | AT17: 0 | AU17: 0.34 | AV17: 0 | AW17: 0.3 | AX17: 0 | AY17: 0.33 | AZ17: 0 | BA17: 0.35 | BB17: 1 | BC17: 0.35 | BD17: 0 | BE17: 0.36 | BF17: 0
A18: Depreciação, Juros, Impostos e Seguros, Manutenção e Materiais na Operação dos Equipamentos | B18: =HYPERLINK("#"&CELL("address",OFFSET(Analítico!$B$1,MATCH(88827,Analítico!$B:$B,0)-1,3)),88827) | C18: BETONEIRA CAPACIDADE NOMINAL DE 400 L, CAPACIDADE DE MISTURA 280 L, MOTOR ELÉTRICO TRIFÁSICO POTÊNCIA DE 2 CV, SEM CARREGADOR - JUROS. AF_05/2023 | D18: H | E18: 0.08 | F18: 0 | G18: 0.07 | H18: 0 | I18: 0.07 | J18: 0 | K18: 0.08 | L18: 0 | M18: 0.08 | N18: 0 | O18: 0.08 | P18: 0 | Q18: 0.07 | R18: 0 | S18: 0.07 | T18: 0 | U18: 0.08 | V18: 0 | W18: 0.08 | X18: 0 | Y18: 0.09 | Z18: 0 | AA18: 0.07 | AB18: 0 | AC18: 0.08 | AD18: 0 | AE18: 0.08 | AF18: 0 | AG18: 0.08 | AH18: 1 | AI18: 0.08 | AJ18: 0 | AK18: 0.1 | AL18: 0 | AM18: 0.08 | AN18: 0 | AO18: 0.07 | AP18: 0 | AQ18: 0.07 | AR18: 0 | AS18: 0.09 | AT18: 0 | AU18: 0.08 | AV18: 0 | AW18: 0.07 | AX18: 0 | AY18: 0.07 | AZ18: 0 | BA18: 0.08 | BB18: 1 | BC18: 0.08 | BD18: 0 | BE18: 0.08 | BF18: 0
A19: Depreciação, Juros, Impostos e Seguros, Manutenção e Materiais na Operação dos Equipamentos | B19: =HYPERLINK("#"&CELL("address",OFFSET(Analítico!$B$1,MATCH(88828,Analítico!$B:$B,0)-1,3)),88828) | C19: BETONEIRA CAPACIDADE NOMINAL DE 400 L, CAPACIDADE DE MISTURA 280 L, MOTOR ELÉTRICO TRIFÁSICO POTÊNCIA DE 2 CV, SEM CARREGADOR - MANUTENÇÃO. AF_05/2023 | D19: H | E19: 0.4 | F19: 0 | G19: 0.33 | H19: 0 | I19: 0.36 | J19: 0 | K19: 0.41 | L19: 0 | M19: 0.39 | N19: 0 | O19: 0.4 | P19: 0 | Q19: 0.36 | R19: 0 | S19: 0.36 | T19: 0 | U19: 0.4 | V19: 0 | W19: 0.42 | X19: 0 | Y19: 0.45 | Z19: 0 | AA19: 0.34 | AB19: 0 | AC19: 0.4 | AD19: 0 | AE19: 0.41 | AF19: 0 | AG19: 0.39 | AH19: 1 | AI19: 0.38 | AJ19: 0 | AK19: 0.48 | AL19: 0 | AM19: 0.38 | AN19: 0 | AO19: 0.37 | AP19: 0 | AQ19: 0.36 | AR19: 0 | AS19: 0.43 | AT19: 0 | AU19: 0.38 | AV19: 0 | AW19: 0.33 | AX19: 0 | AY19: 0.37 | AZ19: 0 | BA19: 0.39 | BB19: 1 | BC19: 0.39 | BD19: 0 | BE19: 0.39 | BF19: 0
A20: Depreciação, Juros, Impostos e Seguros, Manutenção e Materiais na Operação dos Equipamentos | B20: =HYPERLINK("#"&CELL("address",OFFSET(Analítico!$B$1,MATCH(88829,Analítico!$B:$B,0)-1,3)),88829) | C20: BETONEIRA CAPACIDADE NOMINAL DE 400 L, CAPACIDADE DE MISTURA 280 L, MOTOR ELÉTRICO TRIFÁSICO POTÊNCIA DE 2 CV, SEM CARREGADOR - MATERIAIS NA OPERAÇÃO. AF_05/2023 | D20: H | E20: 1.62 | F20: 0 | G20: 1.38 | H20: 0 | I20: 1.22 | J20: 0 | K20: 1.33 | L20: 0 | M20: 1.42 | N20: 0 | O20: 1.23 | P20: 0 | Q20: 1 | R20: 0 | S20: 1.26 | T20: 0 | U20: 1.47 | V20: 0 | W20: 1.36 | X20: 0 | Y20: 1.45 | Z20: 0 | AA20: 1.6 | AB20: 0 | AC20: 1.46 | AD20: 0 | AE20: 1.52 | AF20: 0 | AG20: 1.07 | AH20: 0 | AI20: 1.28 | AJ20: 0 | AK20: 1.37 | AL20: 0 | AM20: 1.06 | AN20: 0 | AO20: 1.61 | AP20: 0 | AQ20: 1.26 | AR20: 0 | AS20: 2 | AT20: 0 | AU20: 1.23 | AV20: 0 | AW20: 1.4 | AX20: 0 | AY20: 1.11 | AZ20: 0 | BA20: 1.25 | BB20: 0 | BC20: 1.08 | BD20: 0 | BE20: 1.68 | BF20: 0
A21: Livro SINAPI: Cálculos e Parâmetros | B21: =HYPERLINK("#"&CELL("address",OFFSET(Analítico!$B$1,MATCH(95389,Analítico!$B:$B,0)-1,3)),95389) | C21: CURSO DE CAPACITAÇÃO PARA OPERADOR DE BETONEIRA ESTACIONÁRIA/MISTURADOR (ENCARGOS COMPLEMENTARES) - HORISTA | D21: H | E21: 0.14 | F21: 0 | G21: 0.12 | H21: 0 | I21: 0.21 | J21: 0 | K21: 0.12 | L21: 0 | M21: 0.3 | N21: 0 | O21: 0.18 | P21: 0 | Q21: 0.16 | R21: 0 | S21: 0.2 | T21: 0 | U21: 0.12 | V21: 0 | W21: 0.22 | X21: 0 | Y21: 0.19 | Z21: 0 | AA21: 0.19 | AB21: 0 | AC21: 0.14 | AD21: 0 | AE21: 0.17 | AF21: 0 | AG21: 0.13 | AH21: 0 | AI21: 0.14 | AJ21: 0 | AK21: 0.19 | AL21: 0 | AM21: 0.23 | AN21: 0 | AO21: 0.2 | AP21: 0 | AQ21: 0.17 | AR21: 0 | AS21: 0.17 | AT21: 0 | AU21: 0.13 | AV21: 0 | AW21: 0.21 | AX21: 0 | AY21: 0.27 | AZ21: 0 | BA21: 0.17 | BB21: 0 | BC21: 0.22 | BD21: 0 | BE21: 0.13 | BF21: 0
A22: Livro SINAPI: Cálculos e Parâmetros | B22: =HYPERLINK("#"&CELL("address",OFFSET(Analítico!$B$1,MATCH(95371,Analítico!$B:$B,0)-1,3)),95371) | C22: CURSO DE CAPACITAÇÃO PARA PEDREIRO (ENCARGOS COMPLEMENTARES) - HORISTA | D22: H | E22: 0.53 | F22: 0 | G22: 0.42 | H22: 0 | I22: 0.48 | J22: 0 | K22: 0.47 | L22: 0 | M22: 0.54 | N22: 0 | O22: 0.49 | P22: 0 | Q22: 0.51 | R22: 0 | S22: 0.5 | T22: 0 | U22: 0.53 | V22: 0 | W22: 0.47 | X22: 0 | Y22: 0.54 | Z22: 0 | AA22: 0.47 | AB22: 0 | AC22: 0.47 | AD22: 0 | AE22: 0.46 | AF22: 0 | AG22: 0.48 | AH22: 0 | AI22: 0.49 | AJ22: 0 | AK22: 0.46 | AL22: 0 | AM22: 0.65 | AN22: 0 | AO22: 0.62 | AP22: 0 | AQ22: 0.42 | AR22: 0 | AS22: 0.5 | AT22: 0 | AU22: 0.54 | AV22: 0 | AW22: 0.5 | AX22: 0 | AY22: 0.68 | AZ22: 0 | BA22: 0.45 | BB22: 0 | BC22: 0.58 | BD22: 0 | BE22: 0.45 | BF22: 0
A23: Livro SINAPI: Cálculos e Parâmetros | B23: =HYPERLINK("#"&CELL("address",OFFSET(Analítico!$B$1,MATCH(95378,Analítico!$B:$B,0)-1,3)),95378) | C23: CURSO DE CAPACITAÇÃO PARA SERVENTE (ENCARGOS COMPLEMENTARES) - HORISTA | D23: H | E23: 0.36 | F23: 0 | G23: 0.33 | H23: 0 | I23: 0.36 | J23: 0 | K23: 0.34 | L23: 0 | M23: 0.34 | N23: 0 | O23: 0.34 | P23: 0 | Q23: 0.35 | R23: 0 | S23: 0.37 | T23: 0 | U23: 0.33 | V23: 0 | W23: 0.34 | X23: 0 | Y23: 0.36 | Z23: 0 | AA23: 0.35 | AB23: 0 | AC23: 0.35 | AD23: 0 | AE23: 0.34 | AF23: 0 | AG23: 0.36 | AH23: 0 | AI23: 0.37 | AJ23: 0 | AK23: 0.33 | AL23: 0 | AM23: 0.46 | AN23: 0 | AO23: 0.48 | AP23: 0 | AQ23: 0.34 | AR23: 0 | AS23: 0.41 | AT23: 0 | AU23: 0.33 | AV23: 0 | AW23: 0.39 | AX23: 0 | AY23: 0.47 | AZ23: 0 | BA23: 0.33 | BB23: 0 | BC23: 0.47 | BD23: 0 | BE23: 0.33 | BF23: 0
A24: Livro SINAPI: Cálculos e Parâmetros | B24: =HYPERLINK("#"&CELL("address",OFFSET(Analítico!$B$1,MATCH(88377,Analítico!$B:$B,0)-1,3)),88377) | C24: OPERADOR DE BETONEIRA ESTACIONÁRIA/MISTURADOR COM ENCARGOS COMPLEMENTARES | D24: H | E24: 23.91 | F24: 0 | G24: 21.28 | H24: 0 | I24: 35.45 | J24: 0 | K24: 18.88 | L24: 0 | M24: 45.24 | N24: 0 | O24: 30.73 | P24: 0 | Q24: 28.16 | R24: 0 | S24: 35.46 | T24: 0 | U24: 21.64 | V24: 0 | W24: 32.3 | X24: 0 | Y24: 30.06 | Z24: 0 | AA24: 28.54 | AB24: 0 | AC24: 23.81 | AD24: 0 | AE24: 29.89 | AF24: 0 | AG24: 22 | AH24: 0 | AI24: 23.48 | AJ24: 0 | AK24: 28.89 | AL24: 0 | AM24: 37.89 | AN24: 0 | AO24: 34.11 | AP24: 0 | AQ24: 29.2 | AR24: 0 | AS24: 27.12 | AT24: 0 | AU24: 23.7 | AV24: 0 | AW24: 31.85 | AX24: 0 | AY24: 37.49 | AZ24: 0 | BA24: 26.82 | BB24: 0 | BC24: 34.95 | BD24: 0 | BE24: 22.15 | BF24: 0
A25: Livro SINAPI: Cálculos e Parâmetros | B25: =HYPERLINK("#"&CELL("address",OFFSET(Analítico!$B$1,MATCH(88309,Analítico!$B:$B,0)-1,3)),88309) | C25: PEDREIRO COM ENCARGOS COMPLEMENTARES | D25: H | E25: 33.11 | F25: 0 | G25: 27.41 | H25: 0 | I25: 34.24 | J25: 0 | K25: 27.58 | L25: 0 | M25: 35.77 | N25: 0 | O25: 32.77 | P25: 0 | Q25: 33.91 | R25: 0 | S25: 36.29 | T25: 0 | U25: 33.58 | V25: 0 | W25: 29.05 | X25: 0 | Y25: 33.62 | Z25: 0 | AA25: 29.71 | AB25: 0 | AC25: 30.54 | AD25: 0 | AE25: 32.75 | AF25: 0 | AG25: 30.02 | AH25: 0 | AI25: 30.95 | AJ25: 0 | AK25: 29.47 | AL25: 0 | AM25: 42.12 | AN25: 0 | AO25: 40.45 | AP25: 0 | AQ25: 29.7 | AR25: 0 | AS25: 32.17 | AT25: 0 | AU25: 34.29 | AV25: 0 | AW25: 31.11 | AX25: 0 | AY25: 38.1 | AZ25: 0 | BA25: 28.91 | BB25: 0 | BC25: 37.26 | BD25: 0 | BE25: 28.97 | BF25: 0
A26: Livro SINAPI: Cálculos e Parâmetros | B26: =HYPERLINK("#"&CELL("address",OFFSET(Analítico!$B$1,MATCH(88316,Analítico!$B:$B,0)-1,3)),88316) | C26: SERVENTE COM ENCARGOS COMPLEMENTARES | D26: H | E26: 24.98 | F26: 0 | G26: 22.92 | H26: 0 | I26: 28.17 | J26: 0 | K26: 21.32 | L26: 0 | M26: 26.14 | N26: 0 | O26: 25.41 | P26: 0 | Q26: 26.07 | R26: 0 | S26: 30.17 | T26: 0 | U26: 23.53 | V26: 0 | W26: 22.6 | X26: 0 | Y26: 24.88 | Z26: 0 | AA26: 23.65 | AB26: 0 | AC26: 24.68 | AD26: 0 | AE26: 26.88 | AF26: 0 | AG26: 24.05 | AH26: 0 | AI26: 24.98 | AJ26: 0 | AK26: 23.66 | AL26: 0 | AM26: 32.78 | AN26: 0 | AO26: 33.44 | AP26: 0 | AQ26: 25.8 | AR26: 0 | AS26: 27.6 | AT26: 0 | AU26: 24.56 | AV26: 0 | AW26: 25.81 | AX26: 0 | AY26: 28.04 | AZ26: 0 | BA26: 22.83 | BB26: 0 | BC26: 32.18 | BD26: 0 | BE26: 23.34 | BF26: 0

Sheet CCD
A1: SINAPI - Sistema Nacional de Pesquisa de Custos e Índices da Construção Civil
A2: RELATÓRIO DE CUSTOS DE COMPOSIÇÕES - ENCARGOS SOCIAIS COM DESONERAÇÃO
A3: Mês de Referência: | B3: 08/2026 | D3: Encargos sociais sobre a mão de obra:
A4: Data de emissão: | B4: 11/09/2026 | D4: (COM DESONERAÇÃO) | E4: AC | G4: AL | I4: AM | K4: AP | M4: BA | O4: CE | Q4: DF | S4: ES | U4: GO | W4: MA | Y4: MG | AA4: MS | AC4: MT | AE4: PA | AG4: PB | AI4: PE | AK4: PI | AM4: PR | AO4: RJ | AQ4: RN | AS4: RO | AU4: RR | AW4: RS | AY4: SC | BA4: SE | BC4: SP | BE4: TO
D5: Localidade | E5: RIO BRANCO | G5: MACEIO | I5: MANAUS | K5: MACAPA | M5: SALVADOR | O5: FORTALEZA | Q5: BRASILIA | S5: VITORIA | U5: GOIANIA | W5: SAO LUIS | Y5: BELO HORIZONTE | AA5: CAMPO GRANDE | AC5: CUIABA | AE5: BELEM | AG5: JOAO PESSOA | AI5: RECIFE | AK5: TERESINA | AM5: CURITIBA | AO5: RIO DE JANEIRO | AQ5: NATAL | AS5: PORTO VELHO | AU5: BOA VISTA | AW5: PORTO ALEGRE | AY5: FLORIANOPOLIS | BA5: ARACAJU | BC5: SAO PAULO | BE5: PALMAS
A6: Observação: | B6: %AS (porcentagem Atribuído São Paulo) corresponde a porcentagem do custo total da | D6: Horista | E6: 0.9688 | G6: 1.0013 | I6: 0.9835 | K6: 0.9923 | M6: 1.017 | O6: 0.9971 | Q6: 0.9463 | S6: 1.0222 | U6: 0.9322 | W6: 0.9831 | Y6: 1.0033 | AA6: 0.9956 | AC6: 0.9089 | AE6: 1.0326 | AG6: 1.0206 | AI6: 0.9883 | AK6: 0.9796 | AM6: 1.0025 | AO6: 0.9688 | AQ6: 1.0077 | AS6: 0.9961 | AU6: 0.9885 | AW6: 0.9612 | AY6: 0.9838 | BA6: 0.9588 | BC6: 0.9909 | BE6: 0.9923
B7: composição que foi obtida utilizando preços de insumos de São Paulo por indisponibilidade | D7: Mensalista | E7: 0.5653 | G7: 0.5859 | I7: 0.582 | K7: 0.5746 | M7: 0.6013 | O7: 0.5974 | Q7: 0.5745 | S7: 0.6106 | U7: 0.5747 | W7: 0.5866 | Y7: 0.6106 | AA7: 0.5874 | AC7: 0.5603 | AE7: 0.5998 | AG7: 0.5991 | AI7: 0.581 | AK7: 0.5891 | AM7: 0.5965 | AO7: 0.572 | AQ7: 0.5955 | AS7: 0.5792 | AU7: 0.5772 | AW7: 0.5667 | AY7: 0.5822 | BA7: 0.5718 | BC7: 0.5851 | BE7: 0.592
B8: dos preços de insumos necessários à composição no estado em questão. Custo zerado (hífen)
B9: indica que pelo menos um dos itens da composição não tem custo/preço. | E9: AC | G9: AL | I9: AM | K9: AP | M9: BA | O9: CE | Q9: DF | S9: ES | U9: GO | W9: MA | Y9: MG | AA9: MS | AC9: MT | AE9: PA | AG9: PB | AI9: PE | AK9: PI | AM9: PR | AO9: RJ | AQ9: RN | AS9: RO | AU9: RR | AW9: RS | AY9: SC | BA9: SE | BC9: SP | BE9: TO
A10: Grupo | B10: Código da Composição | C10: Descrição | D10: Unidade | E10: Custo (R$) | F10: %AS | G10: Custo (R$) | H10: %AS | I10: Custo (R$) | J10: %AS | K10: Custo (R$) | L10: %AS | M10: Custo (R$) | N10: %AS | O10: Custo (R$) | P10: %AS | Q10: Custo (R$) | R10: %AS | S10: Custo (R$) | T10: %AS | U10: Custo (R$) | V10: %AS | W10: Custo (R$) | X10: %AS | Y10: Custo (R$) | Z10: %AS | AA10: Custo (R$) | AB10: %AS | AC10: Custo (R$) | AD10: %AS | AE10: Custo (R$) | AF10: %AS | AG10: Custo (R$) | AH10: %AS | AI10: Custo (R$) | AJ10: %AS | AK10: Custo (R$) | AL10: %AS | AM10: Custo (R$) | AN10: %AS | AO10: Custo (R$) | AP10: %AS | AQ10: Custo (R$) | AR10: %AS | AS10: Custo (R$) | AT10: %AS | AU10: Custo (R$) | AV10: %AS | AW10: Custo (R$) | AX10: %AS | AY10: Custo (R$) | AZ10: %AS | BA10: Custo (R$) | BB10: %AS | BC10: Custo (R$) | BD10: %AS | BE10: Custo (R$) | BF10: %AS
A11: Acessibilidade | B11: =HYPERLINK("#"&CELL("address",OFFSET(Analítico!$B$1,MATCH(104658,Analítico!$B:$B,0)-1,3)),104658) | C11: PISO PODOTÁTIL DE ALERTA OU DIRECIONAL, DE CONCRETO, ASSENTADO SOBRE ARGAMASSA. AF_03/2024 | D11: M2 | E11: 276.55 | F11: 0 | G11: 161.12 | H11: 0 | I11: 225.64 | J11: 0 | K11: 197.54 | L11: 0 | M11: 168.7 | N11: 0 | O11: 170.07 | P11: 0 | Q11: 183.08 | R11: 0 | S11: 185.31 | T11: 0 | U11: 188.51 | V11: 0 | W11: 173.59 | X11: 0 | Y11: 161.89 | Z11: 0 | AA11: 174.28 | AB11: 0 | AC11: 218.49 | AD11: 0 | AE11: 186.2 | AF11: 0 | AG11: 149.45 | AH11: 0 | AI11: 163.99 | AJ11: 0 | AK11: 151.67 | AL11: 0 | AM11: 154.71 | AN11: 0 | AO11: 186.73 | AP11: 0 | AQ11: 165.19 | AR11: 0 | AS11: 221.05 | AT11: 0 | AU11: 272.78 | AV11: 0 | AW11: 153.96 | AX11: 0 | AY11: 157.5 | AZ11: 0 | BA11: 179.01 | BB11: 0 | BC11: 204.51 | BD11: 0 | BE11: 201.88 | BF11: 0
A12: Acessibilidade | B12: =HYPERLINK("#"&CELL("address",OFFSET(Analítico!$B$1,MATCH(105006,Analítico!$B:$B,0)-1,3)),105006) | C12: RAMPA DE ACESSIBILIDADE EM CONCRETO PRÉ MOLDADO, EM CALÇADA NOVA COM LARGURA MAIOR OU IGUAL À 3,00 M, FCK 25MPA, COM PISO PODOTÁTIL. AF_03/2024 | D12: UN | E12: 0 | G12: 0 | I12: 0 | K12: 0 | M12: 0 | O12: 0 | Q12: 0 | S12: 0 | U12: 0 | W12: 0 | Y12: 0 | AA12: 0 | AC12: 0 | AE12: 0 | AG12: 0 | AI12: 0 | AK12: 0 | AM12: 0 | AO12: 0 | AQ12: 0 | AS12: 0 | AU12: 0 | AW12: 0 | AY12: 0 | BA12: 0 | BC12: 0 | BE12: 0
A13: Argamassas | B13: =HYPERLINK("#"&CELL("address",OFFSET(Analítico!$B$1,MATCH(87286,Analítico!$B:$B,0)-1,3)),87286) | C13: ARGAMASSA TRAÇO 1:1:6 (EM VOLUME DE CIMENTO, CAL E AREIA MÉDIA ÚMIDA) PARA EMBOÇO/MASSA ÚNICA/ASSENTAMENTO DE ALVENARIA DE VEDAÇÃO, PREPARO MECÂNICO COM BETONEIRA ATÉ 600 L. AF_07/2026 | D13: M3 | E13: 954.58 | F13: 0 | G13: 643.89 | H13: 0 | I13: 711.26 | J13: 0 | K13: 722.85 | L13: 0 | M13: 868.61 | N13: 0 | O13: 695.34 | P13: 0 | Q13: 815.34 | R13: 0 | S13: 667.9 | T13: 0 | U13: 745.35 | V13: 0 | W13: 783.69 | X13: 0 | Y13: 703.92 | Z13: 0 | AA13: 627.41 | AB13: 0 | AC13: 692.83 | AD13: 0 | AE13: 731.07 | AF13: 0 | AG13: 649.77 | AH13: 0.0043 | AI13: 728.69 | AJ13: 0 | AK13: 713.19 | AL13: 0 | AM13: 637.03 | AN13: 0 | AO13: 633.88 | AP13: 0 | AQ13: 611.55 | AR13: 0 | AS13: 873.5 | AT13: 0 | AU13: 793.37 | AV13: 0 | AW13: 641.79 | AX13: 0 | AY13: 711.73 | AZ13: 0 | BA13: 678.66 | BB13: 0.0042 | BC13: 597.45 | BD13: 0 | BE13: 743.33 | BF13: 0
A14: Argamassas | B14: =HYPERLINK("#"&CELL("address",OFFSET(Analítico!$B$1,MATCH(87307,Analítico!$B:$B,0)-1,3)),87307) | C14: ARGAMASSA TRAÇO 1:6 (EM VOLUME DE CIMENTO E AREIA MÉDIA ÚMIDA) PARA CONTRAPISO, PREPARO MECÂNICO COM BETONEIRA ATÉ 600 L. AF_07/2026 | D14: M3 | E14: 793.04 | F14: 0 | G14: 603.68 | H14: 0 | I14: 672.98 | J14: 0 | K14: 696.58 | L14: 0 | M14: 779.42 | N14: 0 | O14: 638.97 | P14: 0 | Q14: 762.92 | R14: 0 | S14: 562.06 | T14: 0 | U14: 718.48 | V14: 0 | W14: 750.3 | X14: 0 | Y14: 652.74 | Z14: 0 | AA14: 561.71 | AB14: 0 | AC14: 661.66 | AD14: 0 | AE14: 686.23 | AF14: 0 | AG14: 609.96 | AH14: 0.0043 | AI14: 627.35 | AJ14: 0 | AK14: 665.36 | AL14: 0 | AM14: 626.21 | AN14: 0 | AO14: 550.38 | AP14: 0 | AQ14: 630.1 | AR14: 0 | AS14: 834.99 | AT14: 0 | AU14: 778.34 | AV14: 0 | AW14: 609.92 | AX14: 0 | AY14: 700.45 | AZ14: 0 | BA14: 616.03 | BB14: 0.0043 | BC14: 540.75 | BD14: 0 | BE14: 678.06 | BF14: 0
A15: Custos Horários Produtivo e Improdutivo dos Equipamentos | B15: =HYPERLINK("#"&CELL("address",OFFSET(Analítico!$B$1,MATCH(88831,Analítico!$B:$B,0)-1,3)),88831) | C15: BETONEIRA CAPACIDADE NOMINAL DE 400 L, CAPACIDADE DE MISTURA 280 L, MOTOR ELÉTRICO TRIFÁSICO POTÊNCIA DE 2 CV, SEM CARREGADOR - CHI DIURNO. AF_05/2023 | D15: CHI | E15: 0.44 | F15: 0 | G15: 0.37 | H15: 0 | I15: 0.4 | J15: 0 | K15: 0.46 | L15: 0 | M15: 0.43 | N15: 0 | O15: 0.45 | P15: 0 | Q15: 0.4 | R15: 0 | S15: 0.4 | T15: 0 | U15: 0.45 | V15: 0 | W15: 0.46 | X15: 0 | Y15: 0.5 | Z15: 0 | AA15: 0.38 | AB15: 0 | AC15: 0.45 | AD15: 0 | AE15: 0.46 | AF15: 0 | AG15: 0.43 | AH15: 1 | AI15: 0.42 | AJ15: 0 | AK15: 0.54 | AL15: 0 | AM15: 0.43 | AN15: 0 | AO15: 0.41 | AP15: 0 | AQ15: 0.4 | AR15: 0 | AS15: 0.48 | AT15: 0 | AU15: 0.42 | AV15: 0 | AW15: 0.37 | AX15: 0 | AY15: 0.4 | AZ15: 0 | BA15: 0.43 | BB15: 1 | BC15: 0.43 | BD15: 0 | BE15: 0.44 | BF15: 0
A16: Custos Horários Produtivo e Improdutivo dos Equipamentos | B16: =HYPERLINK("#"&CELL("address",OFFSET(Analítico!$B$1,MATCH(88830,Analítico!$B:$B,0)-1,3)),88830) | C16: BETONEIRA CAPACIDADE NOMINAL DE 400 L, CAPACIDADE DE MISTURA 280 L, MOTOR ELÉTRICO TRIFÁSICO POTÊNCIA DE 2 CV, SEM CARREGADOR - CHP DIURNO. AF_05/2023 | D16: CHP | E16: 2.46 | F16: 0 | G16: 2.08 | H16: 0 | I16: 1.98 | J16: 0 | K16: 2.2 | L16: 0 | M16: 2.24 | N16: 0 | O16: 2.08 | P16: 0 | Q16: 1.76 | R16: 0 | S16: 2.02 | T16: 0 | U16: 2.32 | V16: 0 | W16: 2.24 | X16: 0 | Y16: 2.4 | Z16: 0 | AA16: 2.32 | AB16: 0 | AC16: 2.31 | AD16: 0 | AE16: 2.39 | AF16: 0 | AG16: 1.89 | AH16: 0.4339 | AI16: 2.08 | AJ16: 0 | AK16: 2.39 | AL16: 0 | AM16: 1.87 | AN16: 0 | AO16: 2.39 | AP16: 0 | AQ16: 2.02 | AR16: 0 | AS16: 2.91 | AT16: 0 | AU16: 2.03 | AV16: 0 | AW16: 2.1 | AX16: 0 | AY16: 1.88 | AZ16: 0 | BA16: 2.07 | BB16: 0.3961 | BC16: 1.9 | BD16: 0 | BE16: 2.51 | BF16: 0
A17: Depreciação, Juros, Impostos e Seguros, Manutenção e Materiais na Operação dos Equipamentos | B17: =HYPERLINK("#"&CELL("address",OFFSET(Analítico!$B$1,MATCH(88826,Analítico!$B:$B,0)-1,3)),88826) | C17: BETONEIRA CAPACIDADE NOMINAL DE 400 L, CAPACIDADE DE MISTURA 280 L, MOTOR ELÉTRICO TRIFÁSICO POTÊNCIA DE 2 CV, SEM CARREGADOR - DEPRECIAÇÃO. AF_05/2023 | D17: H | E17: 0.36 | F17: 0 | G17: 0.3 | H17: 0 | I17: 0.33 | J17: 0 | K17: 0.38 | L17: 0 | M17: 0.35 | N17: 0 | O17: 0.37 | P17: 0 | Q17: 0.33 | R17: 0 | S17: 0.33 | T17: 0 | U17: 0.37 | V17: 0 | W17: 0.38 | X17: 0 | Y17: 0.41 | Z17: 0 | AA17: 0.31 | AB17: 0 | AC17: 0.37 | AD17: 0 | AE17: 0.38 | AF17: 0 | AG17: 0.35 | AH17: 1 | AI17: 0.34 | AJ17: 0 | AK17: 0.44 | AL17: 0 | AM17: 0.35 | AN17: 0 | AO17: 0.34 | AP17: 0 | AQ17: 0.33 | AR17: 0 | AS17: 0.39 | AT17: 0 | AU17: 0.34 | AV17: 0 | AW17: 0.3 | AX17: 0 | AY17: 0.33 | AZ17: 0 | BA17: 0.35 | BB17: 1 | BC17: 0.35 | BD17: 0 | BE17: 0.36 | BF17: 0
A18: Depreciação, Juros, Impostos e Seguros, Manutenção e Materiais na Operação dos Equipamentos | B18: =HYPERLINK("#"&CELL("address",OFFSET(Analítico!$B$1,MATCH(88827,Analítico!$B:$B,0)-1,3)),88827) | C18: BETONEIRA CAPACIDADE NOMINAL DE 400 L, CAPACIDADE DE MISTURA 280 L, MOTOR ELÉTRICO TRIFÁSICO POTÊNCIA DE 2 CV, SEM CARREGADOR - JUROS. AF_05/2023 | D18: H | E18: 0.08 | F18: 0 | G18: 0.07 | H18: 0 | I18: 0.07 | J18: 0 | K18: 0.08 | L18: 0 | M18: 0.08 | N18: 0 | O18: 0.08 | P18: 0 | Q18: 0.07 | R18: 0 | S18: 0.07 | T18: 0 | U18: 0.08 | V18: 0 | W18: 0.08 | X18: 0 | Y18: 0.09 | Z18: 0 | AA18: 0.07 | AB18: 0 | AC18: 0.08 | AD18: 0 | AE18: 0.08 | AF18: 0 | AG18: 0.08 | AH18: 1 | AI18: 0.08 | AJ18: 0 | AK18: 0.1 | AL18: 0 | AM18: 0.08 | AN18: 0 | AO18: 0.07 | AP18: 0 | AQ18: 0.07 | AR18: 0 | AS18: 0.09 | AT18: 0 | AU18: 0.08 | AV18: 0 | AW18: 0.07 | AX18: 0 | AY18: 0.07 | AZ18: 0 | BA18: 0.08 | BB18: 1 | BC18: 0.08 | BD18: 0 | BE18: 0.08 | BF18: 0
A19: Depreciação, Juros, Impostos e Seguros, Manutenção e Materiais na Operação dos Equipamentos | B19: =HYPERLINK("#"&CELL("address",OFFSET(Analítico!$B$1,MATCH(88828,Analítico!$B:$B,0)-1,3)),88828) | C19: BETONEIRA CAPACIDADE NOMINAL DE 400 L, CAPACIDADE DE MISTURA 280 L, MOTOR ELÉTRICO TRIFÁSICO POTÊNCIA DE 2 CV, SEM CARREGADOR - MANUTENÇÃO. AF_05/2023 | D19: H | E19: 0.4 | F19: 0 | G19: 0.33 | H19: 0 | I19: 0.36 | J19: 0 | K19: 0.41 | L19: 0 | M19: 0.39 | N19: 0 | O19: 0.4 | P19: 0 | Q19: 0.36 | R19: 0 | S19: 0.36 | T19: 0 | U19: 0.4 | V19: 0 | W19: 0.42 | X19: 0 | Y19: 0.45 | Z19: 0 | AA19: 0.34 | AB19: 0 | AC19: 0.4 | AD19: 0 | AE19: 0.41 | AF19: 0 | AG19: 0.39 | AH19: 1 | AI19: 0.38 | AJ19: 0 | AK19: 0.48 | AL19: 0 | AM19: 0.38 | AN19: 0 | AO19: 0.37 | AP19: 0 | AQ19: 0.36 | AR19: 0 | AS19: 0.43 | AT19: 0 | AU19: 0.38 | AV19: 0 | AW19: 0.33 | AX19: 0 | AY19: 0.37 | AZ19: 0 | BA19: 0.39 | BB19: 1 | BC19: 0.39 | BD19: 0 | BE19: 0.39 | BF19: 0
A20: Depreciação, Juros, Impostos e Seguros, Manutenção e Materiais na Operação dos Equipamentos | B20: =HYPERLINK("#"&CELL("address",OFFSET(Analítico!$B$1,MATCH(88829,Analítico!$B:$B,0)-1,3)),88829) | C20: BETONEIRA CAPACIDADE NOMINAL DE 400 L, CAPACIDADE DE MISTURA 280 L, MOTOR ELÉTRICO TRIFÁSICO POTÊNCIA DE 2 CV, SEM CARREGADOR - MATERIAIS NA OPERAÇÃO. AF_05/2023 | D20: H | E20: 1.62 | F20: 0 | G20: 1.38 | H20: 0 | I20: 1.22 | J20: 0 | K20: 1.33 | L20: 0 | M20: 1.42 | N20: 0 | O20: 1.23 | P20: 0 | Q20: 1 | R20: 0 | S20: 1.26 | T20: 0 | U20: 1.47 | V20: 0 | W20: 1.36 | X20: 0 | Y20: 1.45 | Z20: 0 | AA20: 1.6 | AB20: 0 | AC20: 1.46 | AD20: 0 | AE20: 1.52 | AF20: 0 | AG20: 1.07 | AH20: 0 | AI20: 1.28 | AJ20: 0 | AK20: 1.37 | AL20: 0 | AM20: 1.06 | AN20: 0 | AO20: 1.61 | AP20: 0 | AQ20: 1.26 | AR20: 0 | AS20: 2 | AT20: 0 | AU20: 1.23 | AV20: 0 | AW20: 1.4 | AX20: 0 | AY20: 1.11 | AZ20: 0 | BA20: 1.25 | BB20: 0 | BC20: 1.08 | BD20: 0 | BE20: 1.68 | BF20: 0
